Workbook
Name budget: 'Budget Dashboard'!$L1
Name budget_range: 'Budget Dashboard'!$Q1
Name budget_rank: 'Budget Dashboard'!$R1
Name cc_budget: Calculations!$K1
Name cc_delta: Calculations!$L1
Name cc_in_focus: Calculations!$G1
Name cc_month_number: Calculations!$F1
Name cc_show_remaining_budget: Calculations!$I1
Name cc_show_type: Calculations!$H1
Name cc_tracked: Calculations!$J1
Name cc_type: Calculations!$E1
Name comb_rank: 'Budget Dashboard'!$S1
Name comb_rank_norm: 'Budget Dashboard'!$U1
Name comb_rank_norm_run_range: 'Budget Dashboard'!$V1
Name comb_rank_range: 'Budget Dashboard'!$T1
Name comb_rank_unique: 'Budget Dashboard'!$W1
Name curren_date: TODAY()
Name expenses_header_row: ROW(Expenses[[#Headers],[ Expenses]])
Name expenses_max_row: MAX(ROW(Expenses[]))
Name expenses_min_row: MIN(ROW(Expenses[]))
Name expenses_total_row: ROW('Budget Planning'!$C$41)
Name header_row_id: 'Budget Dashboard'!$D1
Name Income_header_row: ROW(Income[[#Headers],[Income]])
Name income_max_row: MAX(ROW(Income[]))
Name income_min_row: MIN(ROW(Income[]))
Name income_total_row: ROW('Budget Planning'!$C$24)
Name is_cat: 'Budget Dashboard'!$F1
Name is_empty: 'Budget Dashboard'!$H1
Name is_header: 'Budget Dashboard'!$E1
Name is_total: 'Budget Dashboard'!$G1
Name item: 'Budget Dashboard'!$J1
Name item: 'Budget Dashboard'!$J1
Name out_budget: 'Budget Dashboard'!$AA1
Name out_percentage_completed: 'Budget Dashboard'!$AB1
Name out_tracked: 'Budget Dashboard'!$Z1
Name row_id: 'Budget Dashboard'!$C1
Name savings_header_row: ROW(Savings[[#Headers],[ Savings]])
Name savings_max_row: MAX(ROW(Savings[]))
Name savings_min_row: MIN(ROW(Savings[]))
Name savings_rate_calculation_type: Settings!$E$20
Name savings_total_row: ROW('Budget Planning'!$C$58)
Name selected_period: Calculations!$E$20
Name selected_period_display: Calculations!$E$21
Name selected_year: Calculations!$E$19
Name sort_max_row: 'Budget Dashboard'!$N1
Name sort_min_row: 'Budget Dashboard'!$M1
Name starting_year: Settings!$E$8
Name tracked: 'Budget Dashboard'!$K1
Name tracked_range: 'Budget Dashboard'!$O1
Name tracked_rank: 'Budget Dashboard'!$P1
Name type: 'Budget Dashboard'!$I1
Name type: 'Budget Dashboard'!$I$13

Sheet Settings
A1: Settings
C6: General
D8: Starting Year: | E8: 2026 | G8: Set the starting year (YYYY) once at the beginning and do not change it again
C17: Budget Tracking & Dashboard
D19: KPI Calculation in Dashboard | G19: Choose how you want the savings rate (SR) to be calculated in the dashboard KPI tiles:
D20: Savings Rate as % of Income: | E20: % allocated to Savings | G20: 1) Active Option (% allocated to Savings): SR = Savings / Income
G21: 2) Passive Option (% not allocated to Expenses): SR= (Income - Expenses) / Income

Sheet Budget Planning
A1: Budget Planning
C5: Define the starting year in the settings → | E5: =starting_year -> 2026 | S5: =E5+1 -> 2027 | AG5: =S5+1 -> 2028 | AU5: =AG5+1 -> 2029 | BI5: =AU5+1 -> 2030 | BW5: =BI5+1 -> 2031 | CK5: =BW5+1 -> 2032 | CY5: =CK5+1 -> 2033 | DM5: =CY5+1 -> 2034 | EA5: =DM5+1 -> 2035 | EO5: =EA5+1 -> 2036
E6: =IF(E7=0,"Jan✓","Jan") -> Jan | F6: =IF(F7=0,"Feb✓","Feb") -> Feb✓ | G6: =IF(G7=0,"Mar✓","Mar") -> Mar✓ | H6: =IF(H7=0,"Apr✓","Apr") -> Apr✓ | I6: =IF(I7=0,"May✓","May") -> May✓ | J6: =IF(J7=0,"Jun✓","Jun") -> Jun✓ | K6: =IF(K7=0,"Jul✓","Jul") -> Jul✓ | L6: =IF(L7=0,"Aug✓","Aug") -> Aug✓ | M6: =IF(M7=0,"Sep✓","Sep") -> Sep✓ | N6: =IF(N7=0,"Oct✓","Oct") -> Oct✓ | O6: =IF(O7=0,"Nov✓","Nov") -> Nov✓ | P6: =IF(P7=0,"Dec✓","Dec") -> Dec✓ | Q6: =IF(Q7=0,"Total✓","Total") -> Total | S6: =IF(S7=0,"Jan✓","Jan") -> Jan✓ | T6: =IF(T7=0,"Feb✓","Feb") -> Feb✓ | U6: =IF(U7=0,"Mar✓","Mar") -> Mar✓ | V6: =IF(V7=0,"Apr✓","Apr") -> Apr✓ | W6: =IF(W7=0,"May✓","May") -> May✓ | X6: =IF(X7=0,"Jun✓","Jun") -> Jun✓ | Y6: =IF(Y7=0,"Jul✓","Jul") -> Jul✓ | Z6: =IF(Z7=0,"Aug✓","Aug") -> Aug✓ | AA6: =IF(AA7=0,"Sep✓","Sep") -> Sep✓ | AB6: =IF(AB7=0,"Oct✓","Oct") -> Oct✓ | AC6: =IF(AC7=0,"Nov✓","Nov") -> Nov✓ | AD6: =IF(AD7=0,"Dec✓","Dec") -> Dec✓ | AE6: =IF(AE7=0,"Total✓","Total") -> Total✓ | AG6: =IF(AG7=0,"Jan✓","Jan") -> Jan✓ | AH6: =IF(AH7=0,"Feb✓","Feb") -> Feb✓ | AI6: =IF(AI7=0,"Mar✓","Mar") -> Mar✓ | AJ6: =IF(AJ7=0,"Apr✓","Apr") -> Apr✓ | AK6: =IF(AK7=0,"May✓","May") -> May✓ | AL6: =IF(AL7=0,"Jun✓","Jun") -> Jun✓ | AM6: =IF(AM7=0,"Jul✓","Jul") -> Jul✓ | AN6: =IF(AN7=0,"Aug✓","Aug") -> Aug✓ | AO6: =IF(AO7=0,"Sep✓","Sep") -> Sep✓ | AP6: =IF(AP7=0,"Oct✓","Oct") -> Oct✓ | AQ6: =IF(AQ7=0,"Nov✓","Nov") -> Nov✓ | AR6: =IF(AR7=0,"Dec✓","Dec") -> Dec✓ | AS6: =IF(AS7=0,"Total✓","Total") -> Total✓ | AU6: =IF(AU7=0,"Jan✓","Jan") -> Jan✓ | AV6: =IF(AV7=0,"Feb✓","Feb") -> Feb✓ | AW6: =IF(AW7=0,"Mar✓","Mar") -> Mar✓ | AX6: =IF(AX7=0,"Apr✓","Apr") -> Apr✓ | AY6: =IF(AY7=0,"May✓","May") -> May✓ | AZ6: =IF(AZ7=0,"Jun✓","Jun") -> Jun✓ | BA6: =IF(BA7=0,"Jul✓","Jul") -> Jul✓ | BB6: =IF(BB7=0,"Aug✓","Aug") -> Aug✓ | BC6: =IF(BC7=0,"Sep✓","Sep") -> Sep✓ | BD6: =IF(BD7=0,"Oct✓","Oct") -> Oct✓ | BE6: =IF(BE7=0,"Nov✓","Nov") -> Nov✓ | BF6: =IF(BF7=0,"Dec✓","Dec") -> Dec✓ | BG6: =IF(BG7=0,"Total✓","Total") -> Total✓ | BI6: =IF(BI7=0,"Jan✓","Jan") -> Jan✓ | BJ6: =IF(BJ7=0,"Feb✓","Feb") -> Feb✓ | BK6: =IF(BK7=0,"Mar✓","Mar") -> Mar✓ | BL6: =IF(BL7=0,"Apr✓","Apr") -> Apr✓ | BM6: =IF(BM7=0,"May✓","May") -> May✓ | BN6: =IF(BN7=0,"Jun✓","Jun") -> Jun✓ | BO6: =IF(BO7=0,"Jul✓","Jul") -> Jul✓ | BP6: =IF(BP7=0,"Aug✓","Aug") -> Aug✓ | BQ6: =IF(BQ7=0,"Sep✓","Sep") -> Sep✓ | BR6: =IF(BR7=0,"Oct✓","Oct") -> Oct✓ | BS6: =IF(BS7=0,"Nov✓","Nov") -> Nov✓ | BT6: =IF(BT7=0,"Dec✓","Dec") -> Dec✓ | BU6: =IF(BU7=0,"Total✓","Total") -> Total✓ | BW6: =IF(BW7=0,"Jan✓","Jan") -> Jan✓ | BX6: =IF(BX7=0,"Feb✓","Feb") -> Feb✓ | BY6: =IF(BY7=0,"Mar✓","Mar") -> Mar✓ | BZ6: =IF(BZ7=0,"Apr✓","Apr") -> Apr✓ | CA6: =IF(CA7=0,"May✓","May") -> May✓ | CB6: =IF(CB7=0,"Jun✓","Jun") -> Jun✓ | CC6: =IF(CC7=0,"Jul✓","Jul") -> Jul✓ | CD6: =IF(CD7=0,"Aug✓","Aug") -> Aug✓ | CE6: =IF(CE7=0,"Sep✓","Sep") -> Sep✓ | CF6: =IF(CF7=0,"Oct✓","Oct") -> Oct✓ | CG6: =IF(CG7=0,"Nov✓","Nov") -> Nov✓ | CH6: =IF(CH7=0,"Dec✓","Dec") -> Dec✓ | CI6: =IF(CI7=0,"Total✓","Total") -> Total✓ | CK6: =IF(CK7=0,"Jan✓","Jan") -> Jan✓ | CL6: =IF(CL7=0,"Feb✓","Feb") -> Feb✓ | CM6: =IF(CM7=0,"Mar✓","Mar") -> Mar✓ | CN6: =IF(CN7=0,"Apr✓","Apr") -> Apr✓ | CO6: =IF(CO7=0,"May✓","May") -> May✓ | CP6: =IF(CP7=0,"Jun✓","Jun") -> Jun✓ | CQ6: =IF(CQ7=0,"Jul✓","Jul") -> Jul✓ | CR6: =IF(CR7=0,"Aug✓","Aug") -> Aug✓ | CS6: =IF(CS7=0,"Sep✓","Sep") -> Sep✓ | CT6: =IF(CT7=0,"Oct✓","Oct") -> Oct✓ | CU6: =IF(CU7=0,"Nov✓","Nov") -> Nov✓ | CV6: =IF(CV7=0,"Dec✓","Dec") -> Dec✓ | CW6: =IF(CW7=0,"Total✓","Total") -> Total✓ | CY6: =IF(CY7=0,"Jan✓","Jan") -> Jan✓ | CZ6: =IF(CZ7=0,"Feb✓","Feb") -> Feb✓ | DA6: =IF(DA7=0,"Mar✓","Mar") -> Mar✓ | DB6: =IF(DB7=0,"Apr✓","Apr") -> Apr✓ | DC6: =IF(DC7=0,"May✓","May") -> May✓ | DD6: =IF(DD7=0,"Jun✓","Jun") -> Jun✓ | DE6: =IF(DE7=0,"Jul✓","Jul") -> Jul✓ | DF6: =IF(DF7=0,"Aug✓","Aug") -> Aug✓ | DG6: =IF(DG7=0,"Sep✓","Sep") -> Sep✓ | DH6: =IF(DH7=0,"Oct✓","Oct") -> Oct✓ | DI6: =IF(DI7=0,"Nov✓","Nov") -> Nov✓ | DJ6: =IF(DJ7=0,"Dec✓","Dec") -> Dec✓ | DK6: =IF(DK7=0,"Total✓","Total") -> Total✓ | DM6: =IF(DM7=0,"Jan✓","Jan") -> Jan✓ | DN6: =IF(DN7=0,"Feb✓","Feb") -> Feb✓ | DO6: =IF(DO7=0,"Mar✓","Mar") -> Mar✓ | DP6: =IF(DP7=0,"Apr✓","Apr") -> Apr✓ | DQ6: =IF(DQ7=0,"May✓","May") -> May✓ | DR6: =IF(DR7=0,"Jun✓","Jun") -> Jun✓ | DS6: =IF(DS7=0,"Jul✓","Jul") -> Jul✓ | DT6: =IF(DT7=0,"Aug✓","Aug") -> Aug✓ | DU6: =IF(DU7=0,"Sep✓","Sep") -> Sep✓ | DV6: =IF(DV7=0,"Oct✓","Oct") -> Oct✓ | DW6: =IF(DW7=0,"Nov✓","Nov") -> Nov✓ | DX6: =IF(DX7=0,"Dec✓","Dec") -> Dec✓ | DY6: =IF(DY7=0,"Total✓","Total") -> Total✓ | EA6: =IF(EA7=0,"Jan✓","Jan") -> Jan✓ | EB6: =IF(EB7=0,"Feb✓","Feb") -> Feb✓ | EC6: =IF(EC7=0,"Mar✓","Mar") -> Mar✓ | ED6: =IF(ED7=0,"Apr✓","Apr") -> Apr✓ | EE6: =IF(EE7=0,"May✓","May") -> May✓ | EF6: =IF(EF7=0,"Jun✓","Jun") -> Jun✓ | EG6: =IF(EG7=0,"Jul✓","Jul") -> Jul✓ | EH6: =IF(EH7=0,"Aug✓","Aug") -> Aug✓ | EI6: =IF(EI7=0,"Sep✓","Sep") -> Sep✓ | EJ6: =IF(EJ7=0,"Oct✓","Oct") -> Oct✓ | EK6: =IF(EK7=0,"Nov✓","Nov") -> Nov✓ | EL6: =IF(EL7=0,"Dec✓","Dec") -> Dec✓ | EM6: =IF(EM7=0,"Total✓","Total") -> Total✓ | EO6: =IF(EO7=0,"Jan✓","Jan") -> Jan✓ | EP6: =IF(EP7=0,"Feb✓","Feb") -> Feb✓ | EQ6: =IF(EQ7=0,"Mar✓","Mar") -> Mar✓ | ER6: =IF(ER7=0,"Apr✓","Apr") -> Apr✓ | ES6: =IF(ES7=0,"May✓","May") -> May✓ | ET6: =IF(ET7=0,"Jun✓","Jun") -> Jun✓ | EU6: =IF(EU7=0,"Jul✓","Jul") -> Jul✓ | EV6: =IF(EV7=0,"Aug✓","Aug") -> Aug✓ | EW6: =IF(EW7=0,"Sep✓","Sep") -> Sep✓ | EX6: =IF(EX7=0,"Oct✓","Oct") -> Oct✓ | EY6: =IF(EY7=0,"Nov✓","Nov") -> Nov✓ | EZ6: =IF(EZ7=0,"Dec✓","Dec") -> Dec✓ | FA6: =IF(FA7=0,"Total✓","Total") -> Total✓
C7: To be Allocated: | E7: =E24-(E41+E58) -> -4978 | F7: =F24-(F41+F58) -> 0 | G7: =G24-(G41+G58) -> 0 | H7: =H24-(H41+H58) -> 0 | I7: =I24-(I41+I58) -> 0 | J7: =J24-(J41+J58) -> 0 | K7: =K24-(K41+K58) -> 0 | L7: =L24-(L41+L58) -> 0 | ... Q7: =Q24-(Q41+Q58) -> -4978 | S7: =S24-(S41+S58) -> 0 | T7: =T24-(T41+T58) -> 0 | U7: =U24-(U41+U58) -> 0 | V7: =V24-(V41+V58) -> 0 | W7: =W24-(W41+W58) -> 0 | X7: =X24-(X41+X58) -> 0 | Y7: =Y24-(Y41+Y58) -> 0 | Z7: =Z24-(Z41+Z58) -> 0 | ... AE7: =AE24-(AE41+AE58) -> 0 | AG7: =AG24-(AG41+AG58) -> 0 | AH7: =AH24-(AH41+AH58) -> 0 | AI7: =AI24-(AI41+AI58) -> 0 | AJ7: =AJ24-(AJ41+AJ58) -> 0 | AK7: =AK24-(AK41+AK58) -> 0 | AL7: =AL24-(AL41+AL58) -> 0 | AM7: =AM24-(AM41+AM58) -> 0 | AN7: =AN24-(AN41+AN58) -> 0 | ... AS7: =AS24-(AS41+AS58) -> 0 | AU7: =AU24-(AU41+AU58) -> 0 | AV7: =AV24-(AV41+AV58) -> 0 | AW7: =AW24-(AW41+AW58) -> 0 | AX7: =AX24-(AX41+AX58) -> 0 | AY7: =AY24-(AY41+AY58) -> 0 | AZ7: =AZ24-(AZ41+AZ58) -> 0 | BA7: =BA24-(BA41+BA58) -> 0 | BB7: =BB24-(BB41+BB58) -> 0 | ... BG7: =BG24-(BG41+BG58) -> 0 | BI7: =BI24-(BI41+BI58) -> 0 | BJ7: =BJ24-(BJ41+BJ58) -> 0 | BK7: =BK24-(BK41+BK58) -> 0 | BL7: =BL24-(BL41+BL58) -> 0 | BM7: =BM24-(BM41+BM58) -> 0 | BN7: =BN24-(BN41+BN58) -> 0 | BO7: =BO24-(BO41+BO58) -> 0 | BP7: =BP24-(BP41+BP58) -> 0 | ... BU7: =BU24-(BU41+BU58) -> 0 | BW7: =BW24-(BW41+BW58) -> 0 | BX7: =BX24-(BX41+BX58) -> 0 | BY7: =BY24-(BY41+BY58) -> 0 | BZ7: =BZ24-(BZ41+BZ58) -> 0 | CA7: =CA24-(CA41+CA58) -> 0 | CB7: =CB24-(CB41+CB58) -> 0 | CC7: =CC24-(CC41+CC58) -> 0 | CD7: =CD24-(CD41+CD58) -> 0 | ... CI7: =CI24-(CI41+CI58) -> 0 | CK7: =CK24-(CK41+CK58) -> 0 | CL7: =CL24-(CL41+CL58) -> 0 | CM7: =CM24-(CM41+CM58) -> 0 | CN7: =CN24-(CN41+CN58) -> 0 | CO7: =CO24-(CO41+CO58) -> 0 | CP7: =CP24-(CP41+CP58) -> 0 | CQ7: =CQ24-(CQ41+CQ58) -> 0 | CR7: =CR24-(CR41+CR58) -> 0 | ... CW7: =CW24-(CW41+CW58) -> 0 | CY7: =CY24-(CY41+CY58) -> 0 | CZ7: =CZ24-(CZ41+CZ58) -> 0 | DA7: =DA24-(DA41+DA58) -> 0 | DB7: =DB24-(DB41+DB58) -> 0 | DC7: =DC24-(DC41+DC58) -> 0 | DD7: =DD24-(DD41+DD58) -> 0 | DE7: =DE24-(DE41+DE58) -> 0 | DF7: =DF24-(DF41+DF58) -> 0 | ... DK7: =DK24-(DK41+DK58) -> 0 | DM7: =DM24-(DM41+DM58) -> 0 | DN7: =DN24-(DN41+DN58) -> 0 | DO7: =DO24-(DO41+DO58) -> 0 | DP7: =DP24-(DP41+DP58) -> 0 | DQ7: =DQ24-(DQ41+DQ58) -> 0 | DR7: =DR24-(DR41+DR58) -> 0 | DS7: =DS24-(DS41+DS58) -> 0 | DT7: =DT24-(DT41+DT58) -> 0 | ... DY7: =DY24-(DY41+DY58) -> 0 | EA7: =EA24-(EA41+EA58) -> 0 | EB7: =EB24-(EB41+EB58) -> 0 | EC7: =EC24-(EC41+EC58) -> 0 | ED7: =ED24-(ED41+ED58) -> 0 | EE7: =EE24-(EE41+EE58) -> 0 | EF7: =EF24-(EF41+EF58) -> 0 | EG7: =EG24-(EG41+EG58) -> 0 | EH7: =EH24-(EH41+EH58) -> 0 | ... EM7: =EM24-(EM41+EM58) -> 0 | EO7: =EO24-(EO41+EO58) -> 0 | EP7: =EP24-(EP41+EP58) -> 0 | EQ7: =EQ24-(EQ41+EQ58) -> 0 | ER7: =ER24-(ER41+ER58) -> 0 | ES7: =ES24-(ES41+ES58) -> 0 | ET7: =ET24-(ET41+ET58) -> 0 | EU7: =EU24-(EU41+EU58) -> 0 | EV7: =EV24-(EV41+EV58) -> 0 | ... FA7: =FA24-(FA41+FA58) -> 0
C9: Income | E9: =DATE(E$5,1,1) -> 46023 | F9: =DATE(E$5,2,1) -> 46054 | G9: =DATE(E$5,3,1) -> 46082 | H9: =DATE(E$5,4,1) -> 46113 | I9: =DATE(E$5,5,1) -> 46143 | J9: =DATE(E$5,6,1) -> 46174 | K9: =DATE(E$5,7,1) -> 46204 | L9: =DATE(E$5,8,1) -> 46235 | M9: =DATE(E$5,9,1) -> 46266 | N9: =DATE(E$5,10,1) -> 46296 | O9: =DATE(E$5,11,1) -> 46327 | P9: =DATE(E$5,12,1) -> 46357 | Q9: =E$5 -> 2026 | S9: =DATE(S$5,1,1) -> 46388 | T9: =DATE(S$5,2,1) -> 46419 | U9: =DATE(S$5,3,1) -> 46447 | V9: =DATE(S$5,4,1) -> 46478 | W9: =DATE(S$5,5,1) -> 46508 | X9: =DATE(S$5,6,1) -> 46539 | Y9: =DATE(S$5,7,1) -> 46569 | Z9: =DATE(S$5,8,1) -> 46600 | AA9: =DATE(S$5,9,1) -> 46631 | AB9: =DATE(S$5,10,1) -> 46661 | AC9: =DATE(S$5,11,1) -> 46692 | AD9: =DATE(S$5,12,1) -> 46722 | AE9: =S$5 -> 2027 | AG9: =DATE(AG$5,1,1) -> 46753 | AH9: =DATE(AG$5,2,1) -> 46784 | AI9: =DATE(AG$5,3,1) -> 46813 | AJ9: =DATE(AG$5,4,1) -> 46844 | AK9: =DATE(AG$5,5,1) -> 46874 | AL9: =DATE(AG$5,6,1) -> 46905 | AM9: =DATE(AG$5,7,1) -> 46935 | AN9: =DATE(AG$5,8,1) -> 46966 | AO9: =DATE(AG$5,9,1) -> 46997 | AP9: =DATE(AG$5,10,1) -> 47027 | AQ9: =DATE(AG$5,11,1) -> 47058 | AR9: =DATE(AG$5,12,1) -> 47088 | AS9: =AG$5 -> 2028 | AU9: =DATE(AU$5,1,1) -> 47119 | AV9: =DATE(AU$5,2,1) -> 47150 | AW9: =DATE(AU$5,3,1) -> 47178 | AX9: =DATE(AU$5,4,1) -> 47209 | AY9: =DATE(AU$5,5,1) -> 47239 | AZ9: =DATE(AU$5,6,1) -> 47270 | BA9: =DATE(AU$5,7,1) -> 47300 | BB9: =DATE(AU$5,8,1) -> 47331 | BC9: =DATE(AU$5,9,1) -> 47362 | BD9: =DATE(AU$5,10,1) -> 47392 | BE9: =DATE(AU$5,11,1) -> 47423 | BF9: =DATE(AU$5,12,1) -> 47453 | BG9: =AU$5 -> 2029 | BI9: =DATE(BI$5,1,1) -> 47484 | BJ9: =DATE(BI$5,2,1) -> 47515 | BK9: =DATE(BI$5,3,1) -> 47543 | BL9: =DATE(BI$5,4,1) -> 47574 | BM9: =DATE(BI$5,5,1) -> 47604 | BN9: =DATE(BI$5,6,1) -> 47635 | BO9: =DATE(BI$5,7,1) -> 47665 | BP9: =DATE(BI$5,8,1) -> 47696 | BQ9: =DATE(BI$5,9,1) -> 47727 | BR9: =DATE(BI$5,10,1) -> 47757 | BS9: =DATE(BI$5,11,1) -> 47788 | BT9: =DATE(BI$5,12,1) -> 47818 | BU9: =BI$5 -> 2030 | BW9: =DATE(BW$5,1,1) -> 47849 | BX9: =DATE(BW$5,2,1) -> 47880 | BY9: =DATE(BW$5,3,1) -> 47908 | BZ9: =DATE(BW$5,4,1) -> 47939 | CA9: =DATE(BW$5,5,1) -> 47969 | CB9: =DATE(BW$5,6,1) -> 48000 | CC9: =DATE(BW$5,7,1) -> 48030 | CD9: =DATE(BW$5,8,1) -> 48061 | CE9: =DATE(BW$5,9,1) -> 48092 | CF9: =DATE(BW$5,10,1) -> 48122 | CG9: =DATE(BW$5,11,1) -> 48153 | CH9: =DATE(BW$5,12,1) -> 48183 | CI9: =BW$5 -> 2031 | CK9: =DATE(CK$5,1,1) -> 48214 | CL9: =DATE(CK$5,2,1) -> 48245 | CM9: =DATE(CK$5,3,1) -> 48274 | CN9: =DATE(CK$5,4,1) -> 48305 | CO9: =DATE(CK$5,5,1) -> 48335 | CP9: =DATE(CK$5,6,1) -> 48366 | CQ9: =DATE(CK$5,7,1) -> 48396 | CR9: =DATE(CK$5,8,1) -> 48427 | CS9: =DATE(CK$5,9,1) -> 48458 | CT9: =DATE(CK$5,10,1) -> 48488 | CU9: =DATE(CK$5,11,1) -> 48519 | CV9: =DATE(CK$5,12,1) -> 48549 | CW9: =CK$5 -> 2032 | CY9: =DATE(CY$5,1,1) -> 48580 | CZ9: =DATE(CY$5,2,1) -> 48611 | DA9: =DATE(CY$5,3,1) -> 48639 | DB9: =DATE(CY$5,4,1) -> 48670 | DC9: =DATE(CY$5,5,1) -> 48700 | DD9: =DATE(CY$5,6,1) -> 48731 | DE9: =DATE(CY$5,7,1) -> 48761 | DF9: =DATE(CY$5,8,1) -> 48792 | DG9: =DATE(CY$5,9,1) -> 48823 | DH9: =DATE(CY$5,10,1) -> 48853 | DI9: =DATE(CY$5,11,1) -> 48884 | DJ9: =DATE(CY$5,12,1) -> 48914 | DK9: =CY$5 -> 2033 | DM9: =DATE(DM$5,1,1) -> 48945 | DN9: =DATE(DM$5,2,1) -> 48976 | DO9: =DATE(DM$5,3,1) -> 49004 | DP9: =DATE(DM$5,4,1) -> 49035 | DQ9: =DATE(DM$5,5,1) -> 49065 | DR9: =DATE(DM$5,6,1) -> 49096 | DS9: =DATE(DM$5,7,1) -> 49126 | DT9: =DATE(DM$5,8,1) -> 49157 | DU9: =DATE(DM$5,9,1) -> 49188 | DV9: =DATE(DM$5,10,1) -> 49218 | DW9: =DATE(DM$5,11,1) -> 49249 | DX9: =DATE(DM$5,12,1) -> 49279 | DY9: =DM$5 -> 2034 | EA9: =DATE(EA$5,1,1) -> 49310 | EB9: =DATE(EA$5,2,1) -> 49341 | EC9: =DATE(EA$5,3,1) -> 49369 | ED9: =DATE(EA$5,4,1) -> 49400 | EE9: =DATE(EA$5,5,1) -> 49430 | EF9: =DATE(EA$5,6,1) -> 49461 | EG9: =DATE(EA$5,7,1) -> 49491 | EH9: =DATE(EA$5,8,1) -> 49522 | EI9: =DATE(EA$5,9,1) -> 49553 | EJ9: =DATE(EA$5,10,1) -> 49583 | EK9: =DATE(EA$5,11,1) -> 49614 | EL9: =DATE(EA$5,12,1) -> 49644 | EM9: =EA$5 -> 2035 | EO9: =DATE(EO$5,1,1) -> 49675 | EP9: =DATE(EO$5,2,1) -> 49706 | EQ9: =DATE(EO$5,3,1) -> 49735 | ER9: =DATE(EO$5,4,1) -> 49766 | ES9: =DATE(EO$5,5,1) -> 49796 | ET9: =DATE(EO$5,6,1) -> 49827 | EU9: =DATE(EO$5,7,1) -> 49857 | EV9: =DATE(EO$5,8,1) -> 49888 | EW9: =DATE(EO$5,9,1) -> 49919 | EX9: =DATE(EO$5,10,1) -> 49949 | EY9: =DATE(EO$5,11,1) -> 49980 | EZ9: =DATE(EO$5,12,1) -> 50010 | FA9: =EO$5 -> 2036
C10: Salary (Net) | E10: 25000 | F10: 80562 | G10: 80562 | H10: 80562 | I10: 80562 | J10: 80562 | K10: 80562 | L10: 80562 | M10: 80562 | N10: 80562 | O10: 80562 | P10: 80562 | Q10: =SUM(E10:P10) -> 911182 | AE10: =SUM(S10:AD10) -> 0 | AS10: =SUM(AG10:AR10) -> 0 | BG10: =SUM(AU10:BF10) -> 0 | BU10: =SUM(BI10:BT10) -> 0 | CI10: =SUM(BW10:CH10) -> 0 | CW10: =SUM(CK10:CV10) -> 0 | DK10: =SUM(CY10:DJ10) -> 0 | DY10: =SUM(DM10:DX10) -> 0 | EM10: =SUM(EA10:EL10) -> 0 | FA10: =SUM(EO10:EZ10) -> 0
C11: Side Hustle (Net) | E11: 950 | F11: 5672 | G11: 11084 | H11: 13467 | I11: 17631 | J11: 21021 | K11: 27087 | L11: 33084 | M11: 39765 | N11: 41098 | O11: 43897 | P11: 44567 | Q11: =SUM(E11:P11) -> 299323 | AE11: =SUM(S11:AD11) -> 0 | AS11: =SUM(AG11:AR11) -> 0 | BG11: =SUM(AU11:BF11) -> 0 | BU11: =SUM(BI11:BT11) -> 0 | CI11: =SUM(BW11:CH11) -> 0 | CW11: =SUM(CK11:CV11) -> 0 | DK11: =SUM(CY11:DJ11) -> 0 | DY11: =SUM(DM11:DX11) -> 0 | EM11: =SUM(EA11:EL11) -> 0 | FA11: =SUM(EO11:EZ11) -> 0
C12: Dividends (Net) | E12: 190 | F12: 120 | G12: 210 | H12: 70 | I12: 260 | J12: 220 | K12: 30 | L12: 70 | M12: 350 | N12: 290 | O12: 70 | P12: 50 | Q12: =SUM(E12:P12) -> 1930 | AE12: =SUM(S12:AD12) -> 0 | AS12: =SUM(AG12:AR12) -> 0 | BG12: =SUM(AU12:BF12) -> 0 | BU12: =SUM(BI12:BT12) -> 0 | CI12: =SUM(BW12:CH12) -> 0 | CW12: =SUM(CK12:CV12) -> 0 | DK12: =SUM(CY12:DJ12) -> 0 | DY12: =SUM(DM12:DX12) -> 0 | EM12: =SUM(EA12:EL12) -> 0 | FA12: =SUM(EO12:EZ12) -> 0
C13: Freelance (Net) | E13: 800 | F13: 2250 | G13: 7700 | H13: 8100 | I13: 9300 | J13: 9900 | K13: 10057 | L13: 11097 | M13: 12156 | N13: 13345 | O13: 13980 | P13: 14763 | Q13: =SUM(E13:P13) -> 113448 | AE13: =SUM(S13:AD13) -> 0 | AS13: =SUM(AG13:AR13) -> 0 | BG13: =SUM(AU13:BF13) -> 0 | BU13: =SUM(BI13:BT13) -> 0 | CI13: =SUM(BW13:CH13) -> 0 | CW13: =SUM(CK13:CV13) -> 0 | DK13: =SUM(CY13:DJ13) -> 0 | DY13: =SUM(DM13:DX13) -> 0 | EM13: =SUM(EA13:EL13) -> 0 | FA13: =SUM(EO13:EZ13) -> 0
C14: Other Income | Q14: =SUM(E14:P14) -> 0 | AE14: =SUM(S14:AD14) -> 0 | AS14: =SUM(AG14:AR14) -> 0 | BG14: =SUM(AU14:BF14) -> 0 | BU14: =SUM(BI14:BT14) -> 0 | CI14: =SUM(BW14:CH14) -> 0 | CW14: =SUM(CK14:CV14) -> 0 | DK14: =SUM(CY14:DJ14) -> 0 | DY14: =SUM(DM14:DX14) -> 0 | EM14: =SUM(EA14:EL14) -> 0 | FA14: =SUM(EO14:EZ14) -> 0
C15: Enter Income Category | Q15: =SUM(E15:P15) -> 0 | AE15: =SUM(S15:AD15) -> 0 | AS15: =SUM(AG15:AR15) -> 0 | BG15: =SUM(AU15:BF15) -> 0 | BU15: =SUM(BI15:BT15) -> 0 | CI15: =SUM(BW15:CH15) -> 0 | CW15: =SUM(CK15:CV15) -> 0 | DK15: =SUM(CY15:DJ15) -> 0 | DY15: =SUM(DM15:DX15) -> 0 | EM15: =SUM(EA15:EL15) -> 0 | FA15: =SUM(EO15:EZ15) -> 0
C16: Enter Income Category | Q16: =SUM(E16:P16) -> 0 | AE16: =SUM(S16:AD16) -> 0 | AS16: =SUM(AG16:AR16) -> 0 | BG16: =SUM(AU16:BF16) -> 0 | BU16: =SUM(BI16:BT16) -> 0 | CI16: =SUM(BW16:CH16) -> 0 | CW16: =SUM(CK16:CV16) -> 0 | DK16: =SUM(CY16:DJ16) -> 0 | DY16: =SUM(DM16:DX16) -> 0 | EM16: =SUM(EA16:EL16) -> 0 | FA16: =SUM(EO16:EZ16) -> 0
C17: Enter Income Category | Q17: =SUM(E17:P17) -> 0 | AE17: =SUM(S17:AD17) -> 0 | AS17: =SUM(AG17:AR17) -> 0 | BG17: =SUM(AU17:BF17) -> 0 | BU17: =SUM(BI17:BT17) -> 0 | CI17: =SUM(BW17:CH17) -> 0 | CW17: =SUM(CK17:CV17) -> 0 | DK17: =SUM(CY17:DJ17) -> 0 | DY17: =SUM(DM17:DX17) -> 0 | EM17: =SUM(EA17:EL17) -> 0 | FA17: =SUM(EO17:EZ17) -> 0
C18: Enter Income Category | Q18: =SUM(E18:P18) -> 0 | AE18: =SUM(S18:AD18) -> 0 | AS18: =SUM(AG18:AR18) -> 0 | BG18: =SUM(AU18:BF18) -> 0 | BU18: =SUM(BI18:BT18) -> 0 | CI18: =SUM(BW18:CH18) -> 0 | CW18: =SUM(CK18:CV18) -> 0 | DK18: =SUM(CY18:DJ18) -> 0 | DY18: =SUM(DM18:DX18) -> 0 | EM18: =SUM(EA18:EL18) -> 0 | FA18: =SUM(EO18:EZ18) -> 0
C19: Enter Income Category | Q19: =SUM(E19:P19) -> 0 | AE19: =SUM(S19:AD19) -> 0 | AS19: =SUM(AG19:AR19) -> 0 | BG19: =SUM(AU19:BF19) -> 0 | BU19: =SUM(BI19:BT19) -> 0 | CI19: =SUM(BW19:CH19) -> 0 | CW19: =SUM(CK19:CV19) -> 0 | DK19: =SUM(CY19:DJ19) -> 0 | DY19: =SUM(DM19:DX19) -> 0 | EM19: =SUM(EA19:EL19) -> 0 | FA19: =SUM(EO19:EZ19) -> 0
C20: Enter Income Category | Q20: =SUM(E20:P20) -> 0 | AE20: =SUM(S20:AD20) -> 0 | AS20: =SUM(AG20:AR20) -> 0 | BG20: =SUM(AU20:BF20) -> 0 | BU20: =SUM(BI20:BT20) -> 0 | CI20: =SUM(BW20:CH20) -> 0 | CW20: =SUM(CK20:CV20) -> 0 | DK20: =SUM(CY20:DJ20) -> 0 | DY20: =SUM(DM20:DX20) -> 0 | EM20: =SUM(EA20:EL20) -> 0 | FA20: =SUM(EO20:EZ20) -> 0
C21: Enter Income Category | Q21: =SUM(E21:P21) -> 0 | AE21: =SUM(S21:AD21) -> 0 | AS21: =SUM(AG21:AR21) -> 0 | BG21: =SUM(AU21:BF21) -> 0 | BU21: =SUM(BI21:BT21) -> 0 | CI21: =SUM(BW21:CH21) -> 0 | CW21: =SUM(CK21:CV21) -> 0 | DK21: =SUM(CY21:DJ21) -> 0 | DY21: =SUM(DM21:DX21) -> 0 | EM21: =SUM(EA21:EL21) -> 0 | FA21: =SUM(EO21:EZ21) -> 0
C22: Enter Income Category | Q22: =SUM(E22:P22) -> 0 | AE22: =SUM(S22:AD22) -> 0 | AS22: =SUM(AG22:AR22) -> 0 | BG22: =SUM(AU22:BF22) -> 0 | BU22: =SUM(BI22:BT22) -> 0 | CI22: =SUM(BW22:CH22) -> 0 | CW22: =SUM(CK22:CV22) -> 0 | DK22: =SUM(CY22:DJ22) -> 0 | DY22: =SUM(DM22:DX22) -> 0 | EM22: =SUM(EA22:EL22) -> 0 | FA22: =SUM(EO22:EZ22) -> 0
C23: Other Income | Q23: =SUM(E23:P23) -> 0 | AE23: =SUM(S23:AD23) -> 0 | AS23: =SUM(AG23:AR23) -> 0 | BG23: =SUM(AU23:BF23) -> 0 | BU23: =SUM(BI23:BT23) -> 0 | CI23: =SUM(BW23:CH23) -> 0 | CW23: =SUM(CK23:CV23) -> 0 | DK23: =SUM(CY23:DJ23) -> 0 | DY23: =SUM(DM23:DX23) -> 0 | EM23: =SUM(EA23:EL23) -> 0 | FA23: =SUM(EO23:EZ23) -> 0
C24: Total | E24: {=SUM(INDIRECT(ADDRESS(income_min_row,COLUMN()) &":"& ADDRESS(income_max_row,COLUMN())))} -> 26940 | F24: {=SUM(INDIRECT(ADDRESS(income_min_row,COLUMN()) &":"& ADDRESS(income_max_row,COLUMN())))} -> 88604 | G24: {=SUM(INDIRECT(ADDRESS(income_min_row,COLUMN()) &":"& ADDRESS(income_max_row,COLUMN())))} -> 99556 | H24: {=SUM(INDIRECT(ADDRESS(income_min_row,COLUMN()) &":"& ADDRESS(income_max_row,COLUMN())))} -> 102199 | I24: {=SUM(INDIRECT(ADDRESS(income_min_row,COLUMN()) &":"& ADDRESS(income_max_row,COLUMN())))} -> 107753 | J24: {=SUM(INDIRECT(ADDRESS(income_min_row,COLUMN()) &":"& ADDRESS(income_max_row,COLUMN())))} -> 111703 | K24: {=SUM(INDIRECT(ADDRESS(income_min_row,COLUMN()) &":"& ADDRESS(income_max_row,COLUMN())))} -> 117736 | L24: {=SUM(INDIRECT(ADDRESS(income_min_row,COLUMN()) &":"& ADDRESS(income_max_row,COLUMN())))} -> 124813 | ... Q24: {=SUM(INDIRECT(ADDRESS(income_min_row,COLUMN()) &":"& ADDRESS(income_max_row,COLUMN())))} -> 1325883 | S24: {=SUM(INDIRECT(ADDRESS(income_min_row,COLUMN()) &":"& ADDRESS(income_max_row,COLUMN())))} -> 0 | T24: {=SUM(INDIRECT(ADDRESS(income_min_row,COLUMN()) &":"& ADDRESS(income_max_row,COLUMN())))} -> 0 | U24: {=SUM(INDIRECT(ADDRESS(income_min_row,COLUMN()) &":"& ADDRESS(income_max_row,COLUMN())))} -> 0 | V24: {=SUM(INDIRECT(ADDRESS(income_min_row,COLUMN()) &":"& ADDRESS(income_max_row,COLUMN())))} -> 0 | W24: {=SUM(INDIRECT(ADDRESS(income_min_row,COLUMN()) &":"& ADDRESS(income_max_row,COLUMN())))} -> 0 | X24: {=SUM(INDIRECT(ADDRESS(income_min_row,COLUMN()) &":"& ADDRESS(income_max_row,COLUMN())))} -> 0 | Y24: {=SUM(INDIRECT(ADDRESS(income_min_row,COLUMN()) &":"& ADDRESS(income_max_row,COLUMN())))} -> 0 | Z24: {=SUM(INDIRECT(ADDRESS(income_min_row,COLUMN()) &":"& ADDRESS(income_max_row,COLUMN())))} -> 0 | ... AE24: {=SUM(INDIRECT(ADDRESS(income_min_row,COLUMN()) &":"& ADDRESS(income_max_row,COLUMN())))} -> 0 | AG24: {=SUM(INDIRECT(ADDRESS(income_min_row,COLUMN()) &":"& ADDRESS(income_max_row,COLUMN())))} -> 0 | AH24: {=SUM(INDIRECT(ADDRESS(income_min_row,COLUMN()) &":"& ADDRESS(income_max_row,COLUMN())))} -> 0 | AI24: {=SUM(INDIRECT(ADDRESS(income_min_row,COLUMN()) &":"& ADDRESS(income_max_row,COLUMN())))} -> 0 | AJ24: {=SUM(INDIRECT(ADDRESS(income_min_row,COLUMN()) &":"& ADDRESS(income_max_row,COLUMN())))} -> 0 | AK24: {=SUM(INDIRECT(ADDRESS(income_min_row,COLUMN()) &":"& ADDRESS(income_max_row,COLUMN())))} -> 0 | AL24: {=SUM(INDIRECT(ADDRESS(income_min_row,COLUMN()) &":"& ADDRESS(income_max_row,COLUMN())))} -> 0 | AM24: {=SUM(INDIRECT(ADDRESS(income_min_row,COLUMN()) &":"& ADDRESS(income_max_row,COLUMN())))} -> 0 | AN24: {=SUM(INDIRECT(ADDRESS(income_min_row,COLUMN()) &":"& ADDRESS(income_max_row,COLUMN())))} -> 0 | ... AS24: {=SUM(INDIRECT(ADDRESS(income_min_row,COLUMN()) &":"& ADDRESS(income_max_row,COLUMN())))} -> 0 | AU24: {=SUM(INDIRECT(ADDRESS(income_min_row,COLUMN()) &":"& ADDRESS(income_max_row,COLUMN())))} -> 0 | AV24: {=SUM(INDIRECT(ADDRESS(income_min_row,COLUMN()) &":"& ADDRESS(income_max_row,COLUMN())))} -> 0 | AW24: {=SUM(INDIRECT(ADDRESS(income_min_row,COLUMN()) &":"& ADDRESS(income_max_row,COLUMN())))} -> 0 | AX24: {=SUM(INDIRECT(ADDRESS(income_min_row,COLUMN()) &":"& ADDRESS(income_max_row,COLUMN())))} -> 0 | AY24: {=SUM(INDIRECT(ADDRESS(income_min_row,COLUMN()) &":"& ADDRESS(income_max_row,COLUMN())))} -> 0 | AZ24: {=SUM(INDIRECT(ADDRESS(income_min_row,COLUMN()) &":"& ADDRESS(income_max_row,COLUMN())))} -> 0 | BA24: {=SUM(INDIRECT(ADDRESS(income_min_row,COLUMN()) &":"& ADDRESS(income_max_row,COLUMN())))} -> 0 | BB24: {=SUM(INDIRECT(ADDRESS(income_min_row,COLUMN()) &":"& ADDRESS(income_max_row,COLUMN())))} -> 0 | ... BG24: {=SUM(INDIRECT(ADDRESS(income_min_row,COLUMN()) &":"& ADDRESS(income_max_row,COLUMN())))} -> 0 | BI24: {=SUM(INDIRECT(ADDRESS(income_min_row,COLUMN()) &":"& ADDRESS(income_max_row,COLUMN())))} -> 0 | BJ24: {=SUM(INDIRECT(ADDRESS(income_min_row,COLUMN()) &":"& ADDRESS(income_max_row,COLUMN())))} -> 0 | BK24: {=SUM(INDIRECT(ADDRESS(income_min_row,COLUMN()) &":"& ADDRESS(income_max_row,COLUMN())))} -> 0 | BL24: {=SUM(INDIRECT(ADDRESS(income_min_row,COLUMN()) &":"& ADDRESS(income_max_row,COLUMN())))} -> 0 | BM24: {=SUM(INDIRECT(ADDRESS(income_min_row,COLUMN()) &":"& ADDRESS(income_max_row,COLUMN())))} -> 0 | BN24: {=SUM(INDIRECT(ADDRESS(income_min_row,COLUMN()) &":"& ADDRESS(income_max_row,COLUMN())))} -> 0 | BO24: {=SUM(INDIRECT(ADDRESS(income_min_row,COLUMN()) &":"& ADDRESS(income_max_row,COLUMN())))} -> 0 | BP24: {=SUM(INDIRECT(ADDRESS(income_min_row,COLUMN()) &":"& ADDRESS(income_max_row,COLUMN())))} -> 0 | ... BU24: {=SUM(INDIRECT(ADDRESS(income_min_row,COLUMN()) &":"& ADDRESS(income_max_row,COLUMN())))} -> 0 | BW24: {=SUM(INDIRECT(ADDRESS(income_min_row,COLUMN()) &":"& ADDRESS(income_max_row,COLUMN())))} -> 0 | BX24: {=SUM(INDIRECT(ADDRESS(income_min_row,COLUMN()) &":"& ADDRESS(income_max_row,COLUMN())))} -> 0 | BY24: {=SUM(INDIRECT(ADDRESS(income_min_row,COLUMN()) &":"& ADDRESS(income_max_row,COLUMN())))} -> 0 | BZ24: {=SUM(INDIRECT(ADDRESS(income_min_row,COLUMN()) &":"& ADDRESS(income_max_row,COLUMN())))} -> 0 | CA24: {=SUM(INDIRECT(ADDRESS(income_min_row,COLUMN()) &":"& ADDRESS(income_max_row,COLUMN())))} -> 0 | CB24: {=SUM(INDIRECT(ADDRESS(income_min_row,COLUMN()) &":"& ADDRESS(income_max_row,COLUMN())))} -> 0 | CC24: {=SUM(INDIRECT(ADDRESS(income_min_row,COLUMN()) &":"& ADDRESS(income_max_row,COLUMN())))} -> 0 | CD24: {=SUM(INDIRECT(ADDRESS(income_min_row,COLUMN()) &":"& ADDRESS(income_max_row,COLUMN())))} -> 0 | ... CI24: {=SUM(INDIRECT(ADDRESS(income_min_row,COLUMN()) &":"& ADDRESS(income_max_row,COLUMN())))} -> 0 | CK24: {=SUM(INDIRECT(ADDRESS(income_min_row,COLUMN()) &":"& ADDRESS(income_max_row,COLUMN())))} -> 0 | CL24: {=SUM(INDIRECT(ADDRESS(income_min_row,COLUMN()) &":"& ADDRESS(income_max_row,COLUMN())))} -> 0 | CM24: {=SUM(INDIRECT(ADDRESS(income_min_row,COLUMN()) &":"& ADDRESS(income_max_row,COLUMN())))} -> 0 | CN24: {=SUM(INDIRECT(ADDRESS(income_min_row,COLUMN()) &":"& ADDRESS(income_max_row,COLUMN())))} -> 0 | CO24: {=SUM(INDIRECT(ADDRESS(income_min_row,COLUMN()) &":"& ADDRESS(income_max_row,COLUMN())))} -> 0 | CP24: {=SUM(INDIRECT(ADDRESS(income_min_row,COLUMN()) &":"& ADDRESS(income_max_row,COLUMN())))} -> 0 | CQ24: {=SUM(INDIRECT(ADDRESS(income_min_row,COLUMN()) &":"& ADDRESS(income_max_row,COLUMN())))} -> 0 | CR24: {=SUM(INDIRECT(ADDRESS(income_min_row,COLUMN()) &":"& ADDRESS(income_max_row,COLUMN())))} -> 0 | ... CW24: {=SUM(INDIRECT(ADDRESS(income_min_row,COLUMN()) &":"& ADDRESS(income_max_row,COLUMN())))} -> 0 | CY24: {=SUM(INDIRECT(ADDRESS(income_min_row,COLUMN()) &":"& ADDRESS(income_max_row,COLUMN())))} -> 0 | CZ24: {=SUM(INDIRECT(ADDRESS(income_min_row,COLUMN()) &":"& ADDRESS(income_max_row,COLUMN())))} -> 0 | DA24: {=SUM(INDIRECT(ADDRESS(income_min_row,COLUMN()) &":"& ADDRESS(income_max_row,COLUMN())))} -> 0 | DB24: {=SUM(INDIRECT(ADDRESS(income_min_row,COLUMN()) &":"& ADDRESS(income_max_row,COLUMN())))} -> 0 | DC24: {=SUM(INDIRECT(ADDRESS(income_min_row,COLUMN()) &":"& ADDRESS(income_max_row,COLUMN())))} -> 0 | DD24: {=SUM(INDIRECT(ADDRESS(income_min_row,COLUMN()) &":"& ADDRESS(income_max_row,COLUMN())))} -> 0 | DE24: {=SUM(INDIRECT(ADDRESS(income_min_row,COLUMN()) &":"& ADDRESS(income_max_row,COLUMN())))} -> 0 | DF24: {=SUM(INDIRECT(ADDRESS(income_min_row,COLUMN()) &":"& ADDRESS(income_max_row,COLUMN())))} -> 0 | ... DK24: {=SUM(INDIRECT(ADDRESS(income_min_row,COLUMN()) &":"& ADDRESS(income_max_row,COLUMN())))} -> 0 | DM24: {=SUM(INDIRECT(ADDRESS(income_min_row,COLUMN()) &":"& ADDRESS(income_max_row,COLUMN())))} -> 0 | DN24: {=SUM(INDIRECT(ADDRESS(income_min_row,COLUMN()) &":"& ADDRESS(income_max_row,COLUMN())))} -> 0 | DO24: {=SUM(INDIRECT(ADDRESS(income_min_row,COLUMN()) &":"& ADDRESS(income_max_row,COLUMN())))} -> 0 | DP24: {=SUM(INDIRECT(ADDRESS(income_min_row,COLUMN()) &":"& ADDRESS(income_max_row,COLUMN())))} -> 0 | DQ24: {=SUM(INDIRECT(ADDRESS(income_min_row,COLUMN()) &":"& ADDRESS(income_max_row,COLUMN())))} -> 0 | DR24: {=SUM(INDIRECT(ADDRESS(income_min_row,COLUMN()) &":"& ADDRESS(income_max_row,COLUMN())))} -> 0 | DS24: {=SUM(INDIRECT(ADDRESS(income_min_row,COLUMN()) &":"& ADDRESS(income_max_row,COLUMN())))} -> 0 | DT24: {=SUM(INDIRECT(ADDRESS(income_min_row,COLUMN()) &":"& ADDRESS(income_max_row,COLUMN())))} -> 0 | ... DY24: {=SUM(INDIRECT(ADDRESS(income_min_row,COLUMN()) &":"& ADDRESS(income_max_row,COLUMN())))} -> 0 | EA24: {=SUM(INDIRECT(ADDRESS(income_min_row,COLUMN()) &":"& ADDRESS(income_max_row,COLUMN())))} -> 0 | EB24: {=SUM(INDIRECT(ADDRESS(income_min_row,COLUMN()) &":"& ADDRESS(income_max_row,COLUMN())))} -> 0 | EC24: {=SUM(INDIRECT(ADDRESS(income_min_row,COLUMN()) &":"& ADDRESS(income_max_row,COLUMN())))} -> 0 | ED24: {=SUM(INDIRECT(ADDRESS(income_min_row,COLUMN()) &":"& ADDRESS(income_max_row,COLUMN())))} -> 0 | EE24: {=SUM(INDIRECT(ADDRESS(income_min_row,COLUMN()) &":"& ADDRESS(income_max_row,COLUMN())))} -> 0 | EF24: {=SUM(INDIRECT(ADDRESS(income_min_row,COLUMN()) &":"& ADDRESS(income_max_row,COLUMN())))} -> 0 | EG24: {=SUM(INDIRECT(ADDRESS(income_min_row,COLUMN()) &":"& ADDRESS(income_max_row,COLUMN())))} -> 0 | EH24: {=SUM(INDIRECT(ADDRESS(income_min_row,COLUMN()) &":"& ADDRESS(income_max_row,COLUMN())))} -> 0 | ... EM24: {=SUM(INDIRECT(ADDRESS(income_min_row,COLUMN()) &":"& ADDRESS(income_max_row,COLUMN())))} -> 0 | EO24: {=SUM(INDIRECT(ADDRESS(income_min_row,COLUMN()) &":"& ADDRESS(income_max_row,COLUMN())))} -> 0 | EP24: {=SUM(INDIRECT(ADDRESS(income_min_row,COLUMN()) &":"& ADDRESS(income_max_row,COLUMN())))} -> 0 | EQ24: {=SUM(INDIRECT(ADDRESS(income_min_row,COLUMN()) &":"& ADDRESS(income_max_row,COLUMN())))} -> 0 | ER24: {=SUM(INDIRECT(ADDRESS(income_min_row,COLUMN()) &":"& ADDRESS(income_max_row,COLUMN())))} -> 0 | ES24: {=SUM(INDIRECT(ADDRESS(income_min_row,COLUMN()) &":"& ADDRESS(income_max_row,COLUMN())))} -> 0 | ET24: {=SUM(INDIRECT(ADDRESS(income_min_row,COLUMN()) &":"& ADDRESS(income_max_row,COLUMN())))} -> 0 | EU24: {=SUM(INDIRECT(ADDRESS(income_min_row,COLUMN()) &":"& ADDRESS(income_max_row,COLUMN())))} -> 0 | EV24: {=SUM(INDIRECT(ADDRESS(income_min_row,COLUMN()) &":"& ADDRESS(income_max_row,COLUMN())))} -> 0 | ... FA24: {=SUM(INDIRECT(ADDRESS(income_min_row,COLUMN()) &":"& ADDRESS(income_max_row,COLUMN())))} -> 0
C26: Expenses | E26: =DATE(E$5,1,1) -> 46023 | F26: =DATE(E$5,2,1) -> 46054 | G26: =DATE(E$5,3,1) -> 46082 | H26: =DATE(E$5,4,1) -> 46113 | I26: =DATE(E$5,5,1) -> 46143 | J26: =DATE(E$5,6,1) -> 46174 | K26: =DATE(E$5,7,1) -> 46204 | L26: =DATE(E$5,8,1) -> 46235 | M26: =DATE(E$5,9,1) -> 46266 | N26: =DATE(E$5,10,1) -> 46296 | O26: =DATE(E$5,11,1) -> 46327 | P26: =DATE(E$5,12,1) -> 46357 | Q26: =E$5 -> 2026 | S26: =DATE(S$5,1,1) -> 46388 | T26: =DATE(S$5,2,1) -> 46419 | U26: =DATE(S$5,3,1) -> 46447 | V26: =DATE(S$5,4,1) -> 46478 | W26: =DATE(S$5,5,1) -> 46508 | X26: =DATE(S$5,6,1) -> 46539 | Y26: =DATE(S$5,7,1) -> 46569 | Z26: =DATE(S$5,8,1) -> 46600 | AA26: =DATE(S$5,9,1) -> 46631 | AB26: =DATE(S$5,10,1) -> 46661 | AC26: =DATE(S$5,11,1) -> 46692 | AD26: =DATE(S$5,12,1) -> 46722 | AE26: =S$5 -> 2027 | AG26: =DATE(AG$5,1,1) -> 46753 | AH26: =DATE(AG$5,2,1) -> 46784 | AI26: =DATE(AG$5,3,1) -> 46813 | AJ26: =DATE(AG$5,4,1) -> 46844 | AK26: =DATE(AG$5,5,1) -> 46874 | AL26: =DATE(AG$5,6,1) -> 46905 | AM26: =DATE(AG$5,7,1) -> 46935 | AN26: =DATE(AG$5,8,1) -> 46966 | AO26: =DATE(AG$5,9,1) -> 46997 | AP26: =DATE(AG$5,10,1) -> 47027 | AQ26: =DATE(AG$5,11,1) -> 47058 | AR26: =DATE(AG$5,12,1) -> 47088 | AS26: =AG$5 -> 2028 | AU26: =DATE(AU$5,1,1) -> 47119 | AV26: =DATE(AU$5,2,1) -> 47150 | AW26: =DATE(AU$5,3,1) -> 47178 | AX26: =DATE(AU$5,4,1) -> 47209 | AY26: =DATE(AU$5,5,1) -> 47239 | AZ26: =DATE(AU$5,6,1) -> 47270 | BA26: =DATE(AU$5,7,1) -> 47300 | BB26: =DATE(AU$5,8,1) -> 47331 | BC26: =DATE(AU$5,9,1) -> 47362 | BD26: =DATE(AU$5,10,1) -> 47392 | BE26: =DATE(AU$5,11,1) -> 47423 | BF26: =DATE(AU$5,12,1) -> 47453 | BG26: =AU$5 -> 2029 | BI26: =DATE(BI$5,1,1) -> 47484 | BJ26: =DATE(BI$5,2,1) -> 47515 | BK26: =DATE(BI$5,3,1) -> 47543 | BL26: =DATE(BI$5,4,1) -> 47574 | BM26: =DATE(BI$5,5,1) -> 47604 | BN26: =DATE(BI$5,6,1) -> 47635 | BO26: =DATE(BI$5,7,1) -> 47665 | BP26: =DATE(BI$5,8,1) -> 47696 | BQ26: =DATE(BI$5,9,1) -> 47727 | BR26: =DATE(BI$5,10,1) -> 47757 | BS26: =DATE(BI$5,11,1) -> 47788 | BT26: =DATE(BI$5,12,1) -> 47818 | BU26: =BI$5 -> 2030 | BW26: =DATE(BW$5,1,1) -> 47849 | BX26: =DATE(BW$5,2,1) -> 47880 | BY26: =DATE(BW$5,3,1) -> 47908 | BZ26: =DATE(BW$5,4,1) -> 47939 | CA26: =DATE(BW$5,5,1) -> 47969 | CB26: =DATE(BW$5,6,1) -> 48000 | CC26: =DATE(BW$5,7,1) -> 48030 | CD26: =DATE(BW$5,8,1) -> 48061 | CE26: =DATE(BW$5,9,1) -> 48092 | CF26: =DATE(BW$5,10,1) -> 48122 | CG26: =DATE(BW$5,11,1) -> 48153 | CH26: =DATE(BW$5,12,1) -> 48183 | CI26: =BW$5 -> 2031 | CK26: =DATE(CK$5,1,1) -> 48214 | CL26: =DATE(CK$5,2,1) -> 48245 | CM26: =DATE(CK$5,3,1) -> 48274 | CN26: =DATE(CK$5,4,1) -> 48305 | CO26: =DATE(CK$5,5,1) -> 48335 | CP26: =DATE(CK$5,6,1) -> 48366 | CQ26: =DATE(CK$5,7,1) -> 48396 | CR26: =DATE(CK$5,8,1) -> 48427 | CS26: =DATE(CK$5,9,1) -> 48458 | CT26: =DATE(CK$5,10,1) -> 48488 | CU26: =DATE(CK$5,11,1) -> 48519 | CV26: =DATE(CK$5,12,1) -> 48549 | CW26: =CK$5 -> 2032 | CY26: =DATE(CY$5,1,1) -> 48580 | CZ26: =DATE(CY$5,2,1) -> 48611 | DA26: =DATE(CY$5,3,1) -> 48639 | DB26: =DATE(CY$5,4,1) -> 48670 | DC26: =DATE(CY$5,5,1) -> 48700 | DD26: =DATE(CY$5,6,1) -> 48731 | DE26: =DATE(CY$5,7,1) -> 48761 | DF26: =DATE(CY$5,8,1) -> 48792 | DG26: =DATE(CY$5,9,1) -> 48823 | DH26: =DATE(CY$5,10,1) -> 48853 | DI26: =DATE(CY$5,11,1) -> 48884 | DJ26: =DATE(CY$5,12,1) -> 48914 | DK26: =CY$5 -> 2033 | DM26: =DATE(DM$5,1,1) -> 48945 | DN26: =DATE(DM$5,2,1) -> 48976 | DO26: =DATE(DM$5,3,1) -> 49004 | DP26: =DATE(DM$5,4,1) -> 49035 | DQ26: =DATE(DM$5,5,1) -> 49065 | DR26: =DATE(DM$5,6,1) -> 49096 | DS26: =DATE(DM$5,7,1) -> 49126 | DT26: =DATE(DM$5,8,1) -> 49157 | DU26: =DATE(DM$5,9,1) -> 49188 | DV26: =DATE(DM$5,10,1) -> 49218 | DW26: =DATE(DM$5,11,1) -> 49249 | DX26: =DATE(DM$5,12,1) -> 49279 | DY26: =DM$5 -> 2034 | EA26: =DATE(EA$5,1,1) -> 49310 | EB26: =DATE(EA$5,2,1) -> 49341 | EC26: =DATE(EA$5,3,1) -> 49369 | ED26: =DATE(EA$5,4,1) -> 49400 | EE26: =DATE(EA$5,5,1) -> 49430 | EF26: =DATE(EA$5,6,1) -> 49461 | EG26: =DATE(EA$5,7,1) -> 49491 | EH26: =DATE(EA$5,8,1) -> 49522 | EI26: =DATE(EA$5,9,1) -> 49553 | EJ26: =DATE(EA$5,10,1) -> 49583 | EK26: =DATE(EA$5,11,1) -> 49614 | EL26: =DATE(EA$5,12,1) -> 49644 | EM26: =EA$5 -> 2035 | EO26: =DATE(EO$5,1,1) -> 49675 | EP26: =DATE(EO$5,2,1) -> 49706 | EQ26: =DATE(EO$5,3,1) -> 49735 | ER26: =DATE(EO$5,4,1) -> 49766 | ES26: =DATE(EO$5,5,1) -> 49796 | ET26: =DATE(EO$5,6,1) -> 49827 | EU26: =DATE(EO$5,7,1) -> 49857 | EV26: =DATE(EO$5,8,1) -> 49888 | EW26: =DATE(EO$5,9,1) -> 49919 | EX26: =DATE(EO$5,10,1) -> 49949 | EY26: =DATE(EO$5,11,1) -> 49980 | EZ26: =DATE(EO$5,12,1) -> 50010 | FA26: =EO$5 -> 2036
C27: Rent | E27: 8500 | F27: 8500 | G27: 8500 | H27: 22000 | I27: 22000 | J27: 22000 | K27: 22000 | L27: 22000 | M27: 22000 | N27: 22000 | O27: 22000 | P27: 22000 | Q27: =SUM(E27:P27) -> 223500 | AE27: =SUM(S27:AD27) -> 0 | AS27: =SUM(AG27:AR27) -> 0 | BG27: =SUM(AU27:BF27) -> 0 | BU27: =SUM(BI27:BT27) -> 0 | CI27: =SUM(BW27:CH27) -> 0 | CW27: =SUM(CK27:CV27) -> 0 | DK27: =SUM(CY27:DJ27) -> 0 | DY27: =SUM(DM27:DX27) -> 0 | EM27: =SUM(EA27:EL27) -> 0 | FA27: =SUM(EO27:EZ27) -> 0
C28: Fuel | E28: 1500 | F28: 1500 | G28: 1500 | H28: 3500 | I28: 3500 | J28: 3500 | K28: 3500 | L28: 3500 | M28: 3500 | N28: 3500 | O28: 3500 | P28: 3500 | Q28: =SUM(E28:P28) -> 36000 | AE28: =SUM(S28:AD28) -> 0 | AS28: =SUM(AG28:AR28) -> 0 | BG28: =SUM(AU28:BF28) -> 0 | BU28: =SUM(BI28:BT28) -> 0 | CI28: =SUM(BW28:CH28) -> 0 | CW28: =SUM(CK28:CV28) -> 0 | DK28: =SUM(CY28:DJ28) -> 0 | DY28: =SUM(DM28:DX28) -> 0 | EM28: =SUM(EA28:EL28) -> 0 | FA28: =SUM(EO28:EZ28) -> 0
C29: Groceries | E29: 15568 | F29: 15568 | G29: 15568 | H29: 15568 | I29: 15568 | J29: 15568 | K29: 15568 | L29: 15568 | M29: 15568 | N29: 15568 | O29: 15568 | P29: 15568 | Q29: =SUM(E29:P29) -> 186816 | AE29: =SUM(S29:AD29) -> 0 | AS29: =SUM(AG29:AR29) -> 0 | BG29: =SUM(AU29:BF29) -> 0 | BU29: =SUM(BI29:BT29) -> 0 | CI29: =SUM(BW29:CH29) -> 0 | CW29: =SUM(CK29:CV29) -> 0 | DK29: =SUM(CY29:DJ29) -> 0 | DY29: =SUM(DM29:DX29) -> 0 | EM29: =SUM(EA29:EL29) -> 0 | FA29: =SUM(EO29:EZ29) -> 0
C30: MISC | E30: 1000 | F30: 1000 | G30: 1000 | H30: 1000 | I30: 1000 | J30: 1000 | K30: 1000 | L30: 1000 | M30: 1000 | N30: 1000 | O30: 1000 | P30: 1000 | Q30: =SUM(E30:P30) -> 12000 | AE30: =SUM(S30:AD30) -> 0 | AS30: =SUM(AG30:AR30) -> 0 | BG30: =SUM(AU30:BF30) -> 0 | BU30: =SUM(BI30:BT30) -> 0 | CI30: =SUM(BW30:CH30) -> 0 | CW30: =SUM(CK30:CV30) -> 0 | DK30: =SUM(CY30:DJ30) -> 0 | DY30: =SUM(DM30:DX30) -> 0 | EM30: =SUM(EA30:EL30) -> 0 | FA30: =SUM(EO30:EZ30) -> 0
C31: Insurances | E31: 1050 | F31: 1050 | G31: 1050 | H31: 1050 | I31: 1050 | J31: 1050 | K31: 1050 | L31: 1050 | M31: 1050 | N31: 1050 | O31: 1050 | P31: 1050 | Q31: =SUM(E31:P31) -> 12600 | AE31: =SUM(S31:AD31) -> 0 | AS31: =SUM(AG31:AR31) -> 0 | BG31: =SUM(AU31:BF31) -> 0 | BU31: =SUM(BI31:BT31) -> 0 | CI31: =SUM(BW31:CH31) -> 0 | CW31: =SUM(CK31:CV31) -> 0 | DK31: =SUM(CY31:DJ31) -> 0 | DY31: =SUM(DM31:DX31) -> 0 | EM31: =SUM(EA31:EL31) -> 0 | FA31: =SUM(EO31:EZ31) -> 0
C32: Clothing | E32: 0 | F32: 0 | G32: 0 | H32: 0 | I32: 3500 | J32: 0 | K32: 0 | L32: 0 | M32: 5500 | N32: 0 | O32: 0 | P32: 7000 | Q32: =SUM(E32:P32) -> 16000 | AE32: =SUM(S32:AD32) -> 0 | AS32: =SUM(AG32:AR32) -> 0 | BG32: =SUM(AU32:BF32) -> 0 | BU32: =SUM(BI32:BT32) -> 0 | CI32: =SUM(BW32:CH32) -> 0 | CW32: =SUM(CK32:CV32) -> 0 | DK32: =SUM(CY32:DJ32) -> 0 | DY32: =SUM(DM32:DX32) -> 0 | EM32: =SUM(EA32:EL32) -> 0 | FA32: =SUM(EO32:EZ32) -> 0
C33: Wellness&Medicine | E33: 500 | F33: 500 | G33: 500 | H33: 500 | I33: 500 | J33: 500 | K33: 500 | L33: 500 | M33: 500 | N33: 500 | O33: 500 | P33: 500 | Q33: =SUM(E33:P33) -> 6000 | AE33: =SUM(S33:AD33) -> 0 | AS33: =SUM(AG33:AR33) -> 0 | BG33: =SUM(AU33:BF33) -> 0 | BU33: =SUM(BI33:BT33) -> 0 | CI33: =SUM(BW33:CH33) -> 0 | CW33: =SUM(CK33:CV33) -> 0 | DK33: =SUM(CY33:DJ33) -> 0 | DY33: =SUM(DM33:DX33) -> 0 | EM33: =SUM(EA33:EL33) -> 0 | FA33: =SUM(EO33:EZ33) -> 0
C34: Media | E34: 300 | F34: 300 | G34: 300 | H34: 300 | I34: 300 | J34: 300 | K34: 300 | L34: 300 | M34: 300 | N34: 300 | O34: 300 | P34: 300 | Q34: =SUM(E34:P34) -> 3600 | AE34: =SUM(S34:AD34) -> 0 | AS34: =SUM(AG34:AR34) -> 0 | BG34: =SUM(AU34:BF34) -> 0 | BU34: =SUM(BI34:BT34) -> 0 | CI34: =SUM(BW34:CH34) -> 0 | CW34: =SUM(CK34:CV34) -> 0 | DK34: =SUM(CY34:DJ34) -> 0 | DY34: =SUM(DM34:DX34) -> 0 | EM34: =SUM(EA34:EL34) -> 0 | FA34: =SUM(EO34:EZ34) -> 0
C35: Fun & Vacation | E35: 500 | F35: 1500 | G35: 1000 | H35: 2500 | I35: 3000 | J35: 5000 | K35: 5500 | L35: 3000 | M35: 4000 | N35: 2500 | O35: 2000 | P35: 3800 | Q35: =SUM(E35:P35) -> 34300 | AE35: =SUM(S35:AD35) -> 0 | AS35: =SUM(AG35:AR35) -> 0 | BG35: =SUM(AU35:BF35) -> 0 | BU35: =SUM(BI35:BT35) -> 0 | CI35: =SUM(BW35:CH35) -> 0 | CW35: =SUM(CK35:CV35) -> 0 | DK35: =SUM(CY35:DJ35) -> 0 | DY35: =SUM(DM35:DX35) -> 0 | EM35: =SUM(EA35:EL35) -> 0 | FA35: =SUM(EO35:EZ35) -> 0
C36: Enter Expenses Category | Q36: =SUM(E36:P36) -> 0 | AE36: =SUM(S36:AD36) -> 0 | AS36: =SUM(AG36:AR36) -> 0 | BG36: =SUM(AU36:BF36) -> 0 | BU36: =SUM(BI36:BT36) -> 0 | CI36: =SUM(BW36:CH36) -> 0 | CW36: =SUM(CK36:CV36) -> 0 | DK36: =SUM(CY36:DJ36) -> 0 | DY36: =SUM(DM36:DX36) -> 0 | EM36: =SUM(EA36:EL36) -> 0 | FA36: =SUM(EO36:EZ36) -> 0
C37: Enter Expenses Category | Q37: =SUM(E37:P37) -> 0 | AE37: =SUM(S37:AD37) -> 0 | AS37: =SUM(AG37:AR37) -> 0 | BG37: =SUM(AU37:BF37) -> 0 | BU37: =SUM(BI37:BT37) -> 0 | CI37: =SUM(BW37:CH37) -> 0 | CW37: =SUM(CK37:CV37) -> 0 | DK37: =SUM(CY37:DJ37) -> 0 | DY37: =SUM(DM37:DX37) -> 0 | EM37: =SUM(EA37:EL37) -> 0 | FA37: =SUM(EO37:EZ37) -> 0
C38: Enter Expenses Category | Q38: =SUM(E38:P38) -> 0 | AE38: =SUM(S38:AD38) -> 0 | AS38: =SUM(AG38:AR38) -> 0 | BG38: =SUM(AU38:BF38) -> 0 | BU38: =SUM(BI38:BT38) -> 0 | CI38: =SUM(BW38:CH38) -> 0 | CW38: =SUM(CK38:CV38) -> 0 | DK38: =SUM(CY38:DJ38) -> 0 | DY38: =SUM(DM38:DX38) -> 0 | EM38: =SUM(EA38:EL38) -> 0 | FA38: =SUM(EO38:EZ38) -> 0
C39: Enter Expenses Category | Q39: =SUM(E39:P39) -> 0 | AE39: =SUM(S39:AD39) -> 0 | AS39: =SUM(AG39:AR39) -> 0 | BG39: =SUM(AU39:BF39) -> 0 | BU39: =SUM(BI39:BT39) -> 0 | CI39: =SUM(BW39:CH39) -> 0 | CW39: =SUM(CK39:CV39) -> 0 | DK39: =SUM(CY39:DJ39) -> 0 | DY39: =SUM(DM39:DX39) -> 0 | EM39: =SUM(EA39:EL39) -> 0 | FA39: =SUM(EO39:EZ39) -> 0
C40: Enter Expenses Category | Q40: =SUM(E40:P40) -> 0 | AE40: =SUM(S40:AD40) -> 0 | AS40: =SUM(AG40:AR40) -> 0 | BG40: =SUM(AU40:BF40) -> 0 | BU40: =SUM(BI40:BT40) -> 0 | CI40: =SUM(BW40:CH40) -> 0 | CW40: =SUM(CK40:CV40) -> 0 | DK40: =SUM(CY40:DJ40) -> 0 | DY40: =SUM(DM40:DX40) -> 0 | EM40: =SUM(EA40:EL40) -> 0 | FA40: =SUM(EO40:EZ40) -> 0
C41: Total | E41: {=SUM(INDIRECT(ADDRESS(expenses_min_row,COLUMN()) &":"& ADDRESS(expenses_max_row,COLUMN())))} -> 28918 | F41: {=SUM(INDIRECT(ADDRESS(expenses_min_row,COLUMN()) &":"& ADDRESS(expenses_max_row,COLUMN())))} -> 29918 | G41: {=SUM(INDIRECT(ADDRESS(expenses_min_row,COLUMN()) &":"& ADDRESS(expenses_max_row,COLUMN())))} -> 29418 | H41: {=SUM(INDIRECT(ADDRESS(expenses_min_row,COLUMN()) &":"& ADDRESS(expenses_max_row,COLUMN())))} -> 46418 | I41: {=SUM(INDIRECT(ADDRESS(expenses_min_row,COLUMN()) &":"& ADDRESS(expenses_max_row,COLUMN())))} -> 50418 | J41: {=SUM(INDIRECT(ADDRESS(expenses_min_row,COLUMN()) &":"& ADDRESS(expenses_max_row,COLUMN())))} -> 48918 | K41: {=SUM(INDIRECT(ADDRESS(expenses_min_row,COLUMN()) &":"& ADDRESS(expenses_max_row,COLUMN())))} -> 49418 | L41: {=SUM(INDIRECT(ADDRESS(expenses_min_row,COLUMN()) &":"& ADDRESS(expenses_max_row,COLUMN())))} -> 46918 | ... Q41: {=SUM(INDIRECT(ADDRESS(expenses_min_row,COLUMN()) &":"& ADDRESS(expenses_max_row,COLUMN())))} -> 530816 | S41: {=SUM(INDIRECT(ADDRESS(expenses_min_row,COLUMN()) &":"& ADDRESS(expenses_max_row,COLUMN())))} -> 0 | T41: {=SUM(INDIRECT(ADDRESS(expenses_min_row,COLUMN()) &":"& ADDRESS(expenses_max_row,COLUMN())))} -> 0 | U41: {=SUM(INDIRECT(ADDRESS(expenses_min_row,COLUMN()) &":"& ADDRESS(expenses_max_row,COLUMN())))} -> 0 | V41: {=SUM(INDIRECT(ADDRESS(expenses_min_row,COLUMN()) &":"& ADDRESS(expenses_max_row,COLUMN())))} -> 0 | W41: {=SUM(INDIRECT(ADDRESS(expenses_min_row,COLUMN()) &":"& ADDRESS(expenses_max_row,COLUMN())))} -> 0 | X41: {=SUM(INDIRECT(ADDRESS(expenses_min_row,COLUMN()) &":"& ADDRESS(expenses_max_row,COLUMN())))} -> 0 | Y41: {=SUM(INDIRECT(ADDRESS(expenses_min_row,COLUMN()) &":"& ADDRESS(expenses_max_row,COLUMN())))} -> 0 | Z41: {=SUM(INDIRECT(ADDRESS(expenses_min_row,COLUMN()) &":"& ADDRESS(expenses_max_row,COLUMN())))} -> 0 | ... AE41: {=SUM(INDIRECT(ADDRESS(expenses_min_row,COLUMN()) &":"& ADDRESS(expenses_max_row,COLUMN())))} -> 0 | AG41: {=SUM(INDIRECT(ADDRESS(expenses_min_row,COLUMN()) &":"& ADDRESS(expenses_max_row,COLUMN())))} -> 0 | AH41: {=SUM(INDIRECT(ADDRESS(expenses_min_row,COLUMN()) &":"& ADDRESS(expenses_max_row,COLUMN())))} -> 0 | AI41: {=SUM(INDIRECT(ADDRESS(expenses_min_row,COLUMN()) &":"& ADDRESS(expenses_max_row,COLUMN())))} -> 0 | AJ41: {=SUM(INDIRECT(ADDRESS(expenses_min_row,COLUMN()) &":"& ADDRESS(expenses_max_row,COLUMN())))} -> 0 | AK41: {=SUM(INDIRECT(ADDRESS(expenses_min_row,COLUMN()) &":"& ADDRESS(expenses_max_row,COLUMN())))} -> 0 | AL41: {=SUM(INDIRECT(ADDRESS(expenses_min_row,COLUMN()) &":"& ADDRESS(expenses_max_row,COLUMN())))} -> 0 | AM41: {=SUM(INDIRECT(ADDRESS(expenses_min_row,COLUMN()) &":"& ADDRESS(expenses_max_row,COLUMN())))} -> 0 | AN41: {=SUM(INDIRECT(ADDRESS(expenses_min_row,COLUMN()) &":"& ADDRESS(expenses_max_row,COLUMN())))} -> 0 | ... AS41: {=SUM(INDIRECT(ADDRESS(expenses_min_row,COLUMN()) &":"& ADDRESS(expenses_max_row,COLUMN())))} -> 0 | AU41: {=SUM(INDIRECT(ADDRESS(expenses_min_row,COLUMN()) &":"& ADDRESS(expenses_max_row,COLUMN())))} -> 0 | AV41: {=SUM(INDIRECT(ADDRESS(expenses_min_row,COLUMN()) &":"& ADDRESS(expenses_max_row,COLUMN())))} -> 0 | AW41: {=SUM(INDIRECT(ADDRESS(expenses_min_row,COLUMN()) &":"& ADDRESS(expenses_max_row,COLUMN())))} -> 0 | AX41: {=SUM(INDIRECT(ADDRESS(expenses_min_row,COLUMN()) &":"& ADDRESS(expenses_max_row,COLUMN())))} -> 0 | AY41: {=SUM(INDIRECT(ADDRESS(expenses_min_row,COLUMN()) &":"& ADDRESS(expenses_max_row,COLUMN())))} -> 0 | AZ41: {=SUM(INDIRECT(ADDRESS(expenses_min_row,COLUMN()) &":"& ADDRESS(expenses_max_row,COLUMN())))} -> 0 | BA41: {=SUM(INDIRECT(ADDRESS(expenses_min_row,COLUMN()) &":"& ADDRESS(expenses_max_row,COLUMN())))} -> 0 | BB41: {=SUM(INDIRECT(ADDRESS(expenses_min_row,COLUMN()) &":"& ADDRESS(expenses_max_row,COLUMN())))} -> 0 | ... BG41: {=SUM(INDIRECT(ADDRESS(expenses_min_row,COLUMN()) &":"& ADDRESS(expenses_max_row,COLUMN())))} -> 0 | BI41: {=SUM(INDIRECT(ADDRESS(expenses_min_row,COLUMN()) &":"& ADDRESS(expenses_max_row,COLUMN())))} -> 0 | BJ41: {=SUM(INDIRECT(ADDRESS(expenses_min_row,COLUMN()) &":"& ADDRESS(expenses_max_row,COLUMN())))} -> 0 | BK41: {=SUM(INDIRECT(ADDRESS(expenses_min_row,COLUMN()) &":"& ADDRESS(expenses_max_row,COLUMN())))} -> 0 | BL41: {=SUM(INDIRECT(ADDRESS(expenses_min_row,COLUMN()) &":"& ADDRESS(expenses_max_row,COLUMN())))} -> 0 | BM41: {=SUM(INDIRECT(ADDRESS(expenses_min_row,COLUMN()) &":"& ADDRESS(expenses_max_row,COLUMN())))} -> 0 | BN41: {=SUM(INDIRECT(ADDRESS(expenses_min_row,COLUMN()) &":"& ADDRESS(expenses_max_row,COLUMN())))} -> 0 | BO41: {=SUM(INDIRECT(ADDRESS(expenses_min_row,COLUMN()) &":"& ADDRESS(expenses_max_row,COLUMN())))} -> 0 | BP41: {=SUM(INDIRECT(ADDRESS(expenses_min_row,COLUMN()) &":"& ADDRESS(expenses_max_row,COLUMN())))} -> 0 | ... BU41: {=SUM(INDIRECT(ADDRESS(expenses_min_row,COLUMN()) &":"& ADDRESS(expenses_max_row,COLUMN())))} -> 0 | BW41: {=SUM(INDIRECT(ADDRESS(expenses_min_row,COLUMN()) &":"& ADDRESS(expenses_max_row,COLUMN())))} -> 0 | BX41: {=SUM(INDIRECT(ADDRESS(expenses_min_row,COLUMN()) &":"& ADDRESS(expenses_max_row,COLUMN())))} -> 0 | BY41: {=SUM(INDIRECT(ADDRESS(expenses_min_row,COLUMN()) &":"& ADDRESS(expenses_max_row,COLUMN())))} -> 0 | BZ41: {=SUM(INDIRECT(ADDRESS(expenses_min_row,COLUMN()) &":"& ADDRESS(expenses_max_row,COLUMN())))} -> 0 | CA41: {=SUM(INDIRECT(ADDRESS(expenses_min_row,COLUMN()) &":"& ADDRESS(expenses_max_row,COLUMN())))} -> 0 | CB41: {=SUM(INDIRECT(ADDRESS(expenses_min_row,COLUMN()) &":"& ADDRESS(expenses_max_row,COLUMN())))} -> 0 | CC41: {=SUM(INDIRECT(ADDRESS(expenses_min_row,COLUMN()) &":"& ADDRESS(expenses_max_row,COLUMN())))} -> 0 | CD41: {=SUM(INDIRECT(ADDRESS(expenses_min_row,COLUMN()) &":"& ADDRESS(expenses_max_row,COLUMN())))} -> 0 | ... CI41: {=SUM(INDIRECT(ADDRESS(expenses_min_row,COLUMN()) &":"& ADDRESS(expenses_max_row,COLUMN())))} -> 0 | CK41: {=SUM(INDIRECT(ADDRESS(expenses_min_row,COLUMN()) &":"& ADDRESS(expenses_max_row,COLUMN())))} -> 0 | CL41: {=SUM(INDIRECT(ADDRESS(expenses_min_row,COLUMN()) &":"& ADDRESS(expenses_max_row,COLUMN())))} -> 0 | CM41: {=SUM(INDIRECT(ADDRESS(expenses_min_row,COLUMN()) &":"& ADDRESS(expenses_max_row,COLUMN())))} -> 0 | CN41: {=SUM(INDIRECT(ADDRESS(expenses_min_row,COLUMN()) &":"& ADDRESS(expenses_max_row,COLUMN())))} -> 0 | CO41: {=SUM(INDIRECT(ADDRESS(expenses_min_row,COLUMN()) &":"& ADDRESS(expenses_max_row,COLUMN())))} -> 0 | CP41: {=SUM(INDIRECT(ADDRESS(expenses_min_row,COLUMN()) &":"& ADDRESS(expenses_max_row,COLUMN())))} -> 0 | CQ41: {=SUM(INDIRECT(ADDRESS(expenses_min_row,COLUMN()) &":"& ADDRESS(expenses_max_row,COLUMN())))} -> 0 | CR41: {=SUM(INDIRECT(ADDRESS(expenses_min_row,COLUMN()) &":"& ADDRESS(expenses_max_row,COLUMN())))} -> 0 | ... CW41: {=SUM(INDIRECT(ADDRESS(expenses_min_row,COLUMN()) &":"& ADDRESS(expenses_max_row,COLUMN())))} -> 0 | CY41: {=SUM(INDIRECT(ADDRESS(expenses_min_row,COLUMN()) &":"& ADDRESS(expenses_max_row,COLUMN())))} -> 0 | CZ41: {=SUM(INDIRECT(ADDRESS(expenses_min_row,COLUMN()) &":"& ADDRESS(expenses_max_row,COLUMN())))} -> 0 | DA41: {=SUM(INDIRECT(ADDRESS(expenses_min_row,COLUMN()) &":"& ADDRESS(expenses_max_row,COLUMN())))} -> 0 | DB41: {=SUM(INDIRECT(ADDRESS(expenses_min_row,COLUMN()) &":"& ADDRESS(expenses_max_row,COLUMN())))} -> 0 | DC41: {=SUM(INDIRECT(ADDRESS(expenses_min_row,COLUMN()) &":"& ADDRESS(expenses_max_row,COLUMN())))} -> 0 | DD41: {=SUM(INDIRECT(ADDRESS(expenses_min_row,COLUMN()) &":"& ADDRESS(expenses_max_row,COLUMN())))} -> 0 | DE41: {=SUM(INDIRECT(ADDRESS(expenses_min_row,COLUMN()) &":"& ADDRESS(expenses_max_row,COLUMN())))} -> 0 | DF41: {=SUM(INDIRECT(ADDRESS(expenses_min_row,COLUMN()) &":"& ADDRESS(expenses_max_row,COLUMN())))} -> 0 | ... DK41: {=SUM(INDIRECT(ADDRESS(expenses_min_row,COLUMN()) &":"& ADDRESS(expenses_max_row,COLUMN())))} -> 0 | DM41: {=SUM(INDIRECT(ADDRESS(expenses_min_row,COLUMN()) &":"& ADDRESS(expenses_max_row,COLUMN())))} -> 0 | DN41: {=SUM(INDIRECT(ADDRESS(expenses_min_row,COLUMN()) &":"& ADDRESS(expenses_max_row,COLUMN())))} -> 0 | DO41: {=SUM(INDIRECT(ADDRESS(expenses_min_row,COLUMN()) &":"& ADDRESS(expenses_max_row,COLUMN())))} -> 0 | DP41: {=SUM(INDIRECT(ADDRESS(expenses_min_row,COLUMN()) &":"& ADDRESS(expenses_max_row,COLUMN())))} -> 0 | DQ41: {=SUM(INDIRECT(ADDRESS(expenses_min_row,COLUMN()) &":"& ADDRESS(expenses_max_row,COLUMN())))} -> 0 | DR41: {=SUM(INDIRECT(ADDRESS(expenses_min_row,COLUMN()) &":"& ADDRESS(expenses_max_row,COLUMN())))} -> 0 | DS41: {=SUM(INDIRECT(ADDRESS(expenses_min_row,COLUMN()) &":"& ADDRESS(expenses_max_row,COLUMN())))} -> 0 | DT41: {=SUM(INDIRECT(ADDRESS(expenses_min_row,COLUMN()) &":"& ADDRESS(expenses_max_row,COLUMN())))} -> 0 | ... DY41: {=SUM(INDIRECT(ADDRESS(expenses_min_row,COLUMN()) &":"& ADDRESS(expenses_max_row,COLUMN())))} -> 0 | EA41: {=SUM(INDIRECT(ADDRESS(expenses_min_row,COLUMN()) &":"& ADDRESS(expenses_max_row,COLUMN())))} -> 0 | EB41: {=SUM(INDIRECT(ADDRESS(expenses_min_row,COLUMN()) &":"& ADDRESS(expenses_max_row,COLUMN())))} -> 0 | EC41: {=SUM(INDIRECT(ADDRESS(expenses_min_row,COLUMN()) &":"& ADDRESS(expenses_max_row,COLUMN())))} -> 0 | ED41: {=SUM(INDIRECT(ADDRESS(expenses_min_row,COLUMN()) &":"& ADDRESS(expenses_max_row,COLUMN())))} -> 0 | EE41: {=SUM(INDIRECT(ADDRESS(expenses_min_row,COLUMN()) &":"& ADDRESS(expenses_max_row,COLUMN())))} -> 0 | EF41: {=SUM(INDIRECT(ADDRESS(expenses_min_row,COLUMN()) &":"& ADDRESS(expenses_max_row,COLUMN())))} -> 0 | EG41: {=SUM(INDIRECT(ADDRESS(expenses_min_row,COLUMN()) &":"& ADDRESS(expenses_max_row,COLUMN())))} -> 0 | EH41: {=SUM(INDIRECT(ADDRESS(expenses_min_row,COLUMN()) &":"& ADDRESS(expenses_max_row,COLUMN())))} -> 0 | ... EM41: {=SUM(INDIRECT(ADDRESS(expenses_min_row,COLUMN()) &":"& ADDRESS(expenses_max_row,COLUMN())))} -> 0 | EO41: {=SUM(INDIRECT(ADDRESS(expenses_min_row,COLUMN()) &":"& ADDRESS(expenses_max_row,COLUMN())))} -> 0 | EP41: {=SUM(INDIRECT(ADDRESS(expenses_min_row,COLUMN()) &":"& ADDRESS(expenses_max_row,COLUMN())))} -> 0 | EQ41: {=SUM(INDIRECT(ADDRESS(expenses_min_row,COLUMN()) &":"& ADDRESS(expenses_max_row,COLUMN())))} -> 0 | ER41: {=SUM(INDIRECT(ADDRESS(expenses_min_row,COLUMN()) &":"& ADDRESS(expenses_max_row,COLUMN())))} -> 0 | ES41: {=SUM(INDIRECT(ADDRESS(expenses_min_row,COLUMN()) &":"& ADDRESS(expenses_max_row,COLUMN())))} -> 0 | ET41: {=SUM(INDIRECT(ADDRESS(expenses_min_row,COLUMN()) &":"& ADDRESS(expenses_max_row,COLUMN())))} -> 0 | EU41: {=SUM(INDIRECT(ADDRESS(expenses_min_row,COLUMN()) &":"& ADDRESS(expenses_max_row,COLUMN())))} -> 0 | EV41: {=SUM(INDIRECT(ADDRESS(expenses_min_row,COLUMN()) &":"& ADDRESS(expenses_max_row,COLUMN())))} -> 0 | ... FA41: {=SUM(INDIRECT(ADDRESS(expenses_min_row,COLUMN()) &":"& ADDRESS(expenses_max_row,COLUMN())))} -> 0
C43: Savings | E43: =DATE(E$5,1,1) -> 46023 | F43: =DATE(E$5,2,1) -> 46054 | G43: =DATE(E$5,3,1) -> 46082 | H43: =DATE(E$5,4,1) -> 46113 | I43: =DATE(E$5,5,1) -> 46143 | J43: =DATE(E$5,6,1) -> 46174 | K43: =DATE(E$5,7,1) -> 46204 | L43: =DATE(E$5,8,1) -> 46235 | M43: =DATE(E$5,9,1) -> 46266 | N43: =DATE(E$5,10,1) -> 46296 | O43: =DATE(E$5,11,1) -> 46327 | P43: =DATE(E$5,12,1) -> 46357 | Q43: =E$5 -> 2026 | S43: =DATE(S$5,1,1) -> 46388 | T43: =DATE(S$5,2,1) -> 46419 | U43: =DATE(S$5,3,1) -> 46447 | V43: =DATE(S$5,4,1) -> 46478 | W43: =DATE(S$5,5,1) -> 46508 | X43: =DATE(S$5,6,1) -> 46539 | Y43: =DATE(S$5,7,1) -> 46569 | Z43: =DATE(S$5,8,1) -> 46600 | AA43: =DATE(S$5,9,1) -> 46631 | AB43: =DATE(S$5,10,1) -> 46661 | AC43: =DATE(S$5,11,1) -> 46692 | AD43: =DATE(S$5,12,1) -> 46722 | AE43: =S$5 -> 2027 | AG43: =DATE(AG$5,1,1) -> 46753 | AH43: =DATE(AG$5,2,1) -> 46784 | AI43: =DATE(AG$5,3,1) -> 46813 | AJ43: =DATE(AG$5,4,1) -> 46844 | AK43: =DATE(AG$5,5,1) -> 46874 | AL43: =DATE(AG$5,6,1) -> 46905 | AM43: =DATE(AG$5,7,1) -> 46935 | AN43: =DATE(AG$5,8,1) -> 46966 | AO43: =DATE(AG$5,9,1) -> 46997 | AP43: =DATE(AG$5,10,1) -> 47027 | AQ43: =DATE(AG$5,11,1) -> 47058 | AR43: =DATE(AG$5,12,1) -> 47088 | AS43: =AG$5 -> 2028 | AU43: =DATE(AU$5,1,1) -> 47119 | AV43: =DATE(AU$5,2,1) -> 47150 | AW43: =DATE(AU$5,3,1) -> 47178 | AX43: =DATE(AU$5,4,1) -> 47209 | AY43: =DATE(AU$5,5,1) -> 47239 | AZ43: =DATE(AU$5,6,1) -> 47270 | BA43: =DATE(AU$5,7,1) -> 47300 | BB43: =DATE(AU$5,8,1) -> 47331 | BC43: =DATE(AU$5,9,1) -> 47362 | BD43: =DATE(AU$5,10,1) -> 47392 | BE43: =DATE(AU$5,11,1) -> 47423 | BF43: =DATE(AU$5,12,1) -> 47453 | BG43: =AU$5 -> 2029 | BI43: =DATE(BI$5,1,1) -> 47484 | BJ43: =DATE(BI$5,2,1) -> 47515 | BK43: =DATE(BI$5,3,1) -> 47543 | BL43: =DATE(BI$5,4,1) -> 47574 | BM43: =DATE(BI$5,5,1) -> 47604 | BN43: =DATE(BI$5,6,1) -> 47635 | BO43: =DATE(BI$5,7,1) -> 47665 | BP43: =DATE(BI$5,8,1) -> 47696 | BQ43: =DATE(BI$5,9,1) -> 47727 | BR43: =DATE(BI$5,10,1) -> 47757 | BS43: =DATE(BI$5,11,1) -> 47788 | BT43: =DATE(BI$5,12,1) -> 47818 | BU43: =BI$5 -> 2030 | BW43: =DATE(BW$5,1,1) -> 47849 | BX43: =DATE(BW$5,2,1) -> 47880 | BY43: =DATE(BW$5,3,1) -> 47908 | BZ43: =DATE(BW$5,4,1) -> 47939 | CA43: =DATE(BW$5,5,1) -> 47969 | CB43: =DATE(BW$5,6,1) -> 48000 | CC43: =DATE(BW$5,7,1) -> 48030 | CD43: =DATE(BW$5,8,1) -> 48061 | CE43: =DATE(BW$5,9,1) -> 48092 | CF43: =DATE(BW$5,10,1) -> 48122 | CG43: =DATE(BW$5,11,1) -> 48153 | CH43: =DATE(BW$5,12,1) -> 48183 | CI43: =BW$5 -> 2031 | CK43: =DATE(CK$5,1,1) -> 48214 | CL43: =DATE(CK$5,2,1) -> 48245 | CM43: =DATE(CK$5,3,1) -> 48274 | CN43: =DATE(CK$5,4,1) -> 48305 | CO43: =DATE(CK$5,5,1) -> 48335 | CP43: =DATE(CK$5,6,1) -> 48366 | CQ43: =DATE(CK$5,7,1) -> 48396 | CR43: =DATE(CK$5,8,1) -> 48427 | CS43: =DATE(CK$5,9,1) -> 48458 | CT43: =DATE(CK$5,10,1) -> 48488 | CU43: =DATE(CK$5,11,1) -> 48519 | CV43: =DATE(CK$5,12,1) -> 48549 | CW43: =CK$5 -> 2032 | CY43: =DATE(CY$5,1,1) -> 48580 | CZ43: =DATE(CY$5,2,1) -> 48611 | DA43: =DATE(CY$5,3,1) -> 48639 | DB43: =DATE(CY$5,4,1) -> 48670 | DC43: =DATE(CY$5,5,1) -> 48700 | DD43: =DATE(CY$5,6,1) -> 48731 | DE43: =DATE(CY$5,7,1) -> 48761 | DF43: =DATE(CY$5,8,1) -> 48792 | DG43: =DATE(CY$5,9,1) -> 48823 | DH43: =DATE(CY$5,10,1) -> 48853 | DI43: =DATE(CY$5,11,1) -> 48884 | DJ43: =DATE(CY$5,12,1) -> 48914 | DK43: =CY$5 -> 2033 | DM43: =DATE(DM$5,1,1) -> 48945 | DN43: =DATE(DM$5,2,1) -> 48976 | DO43: =DATE(DM$5,3,1) -> 49004 | DP43: =DATE(DM$5,4,1) -> 49035 | DQ43: =DATE(DM$5,5,1) -> 49065 | DR43: =DATE(DM$5,6,1) -> 49096 | DS43: =DATE(DM$5,7,1) -> 49126 | DT43: =DATE(DM$5,8,1) -> 49157 | DU43: =DATE(DM$5,9,1) -> 49188 | DV43: =DATE(DM$5,10,1) -> 49218 | DW43: =DATE(DM$5,11,1) -> 49249 | DX43: =DATE(DM$5,12,1) -> 49279 | DY43: =DM$5 -> 2034 | EA43: =DATE(EA$5,1,1) -> 49310 | EB43: =DATE(EA$5,2,1) -> 49341 | EC43: =DATE(EA$5,3,1) -> 49369 | ED43: =DATE(EA$5,4,1) -> 49400 | EE43: =DATE(EA$5,5,1) -> 49430 | EF43: =DATE(EA$5,6,1) -> 49461 | EG43: =DATE(EA$5,7,1) -> 49491 | EH43: =DATE(EA$5,8,1) -> 49522 | EI43: =DATE(EA$5,9,1) -> 49553 | EJ43: =DATE(EA$5,10,1) -> 49583 | EK43: =DATE(EA$5,11,1) -> 49614 | EL43: =DATE(EA$5,12,1) -> 49644 | EM43: =EA$5 -> 2035 | EO43: =DATE(EO$5,1,1) -> 49675 | EP43: =DATE(EO$5,2,1) -> 49706 | EQ43: =DATE(EO$5,3,1) -> 49735 | ER43: =DATE(EO$5,4,1) -> 49766 | ES43: =DATE(EO$5,5,1) -> 49796 | ET43: =DATE(EO$5,6,1) -> 49827 | EU43: =DATE(EO$5,7,1) -> 49857 | EV43: =DATE(EO$5,8,1) -> 49888 | EW43: =DATE(EO$5,9,1) -> 49919 | EX43: =DATE(EO$5,10,1) -> 49949 | EY43: =DATE(EO$5,11,1) -> 49980 | EZ43: =DATE(EO$5,12,1) -> 50010 | FA43: =EO$5 -> 2036
C44: Emergency Fund | F44: 25000 | G44: 25000 | H44: 25000 | I44: 25000 | J44: 25000 | K44: 25000 | L44: 25000 | M44: 25000 | N44: 25000 | O44: 25000 | P44: 25000 | Q44: =SUM(E44:P44) -> 275000 | AE44: =SUM(S44:AD44) -> 0 | AS44: =SUM(AG44:AR44) -> 0 | BG44: =SUM(AU44:BF44) -> 0 | BU44: =SUM(BI44:BT44) -> 0 | CI44: =SUM(BW44:CH44) -> 0 | CW44: =SUM(CK44:CV44) -> 0 | DK44: =SUM(CY44:DJ44) -> 0 | DY44: =SUM(DM44:DX44) -> 0 | EM44: =SUM(EA44:EL44) -> 0 | FA44: =SUM(EO44:EZ44) -> 0
C45: SIP | E45: 3000 | F45: 10000 | G45: 10000 | H45: 10000 | I45: 10000 | J45: 10000 | K45: 10000 | L45: 10000 | M45: 10000 | N45: 10000 | O45: 10000 | P45: 10000 | Q45: =SUM(E45:P45) -> 113000 | AE45: =SUM(S45:AD45) -> 0 | AS45: =SUM(AG45:AR45) -> 0 | BG45: =SUM(AU45:BF45) -> 0 | BU45: =SUM(BI45:BT45) -> 0 | CI45: =SUM(BW45:CH45) -> 0 | CW45: =SUM(CK45:CV45) -> 0 | DK45: =SUM(CY45:DJ45) -> 0 | DY45: =SUM(DM45:DX45) -> 0 | EM45: =SUM(EA45:EL45) -> 0 | FA45: =SUM(EO45:EZ45) -> 0
C46: Stock Portfolio | F46: 8686 | G46: 10000 | H46: 7500 | I46: 2000 | J46: 5000 | L46: 3000 | M46: 4000 | N46: 20000 | O46: 35000 | P46: 25000 | Q46: =SUM(E46:P46) -> 120186 | AE46: =SUM(S46:AD46) -> 0 | AS46: =SUM(AG46:AR46) -> 0 | BG46: =SUM(AU46:BF46) -> 0 | BU46: =SUM(BI46:BT46) -> 0 | CI46: =SUM(BW46:CH46) -> 0 | CW46: =SUM(CK46:CV46) -> 0 | DK46: =SUM(CY46:DJ46) -> 0 | DY46: =SUM(DM46:DX46) -> 0 | EM46: =SUM(EA46:EL46) -> 0 | FA46: =SUM(EO46:EZ46) -> 0
...

Sheet Budget Tracking
A1: Budget Tracking
C11: Date | D11: Type | E11: Categories | F11: Amount | G11: Details | H11: Balance
C12: 46025 | D12: Income | E12: Salary (Net) | F12: 25000 | G12: Net Salary received | H12: {=SUMPRODUCT(Tracking[Amount],--(Tracking[Date]<=Tracking[[#This Row],[Date]]),(Tracking[Type]<>"Income")*(-1)+(Tracking[Type]="Income"))} -> 25000
C13: 46026 | D13: Savings | E13: SIP | F13: 3000 | H13: {=SUMPRODUCT(Tracking[Amount],--(Tracking[Date]<=Tracking[[#This Row],[Date]]),(Tracking[Type]<>"Income")*(-1)+(Tracking[Type]="Income"))} -> 22000
C14: 46027 | D14: Expenses | E14: Groceries | F14: 2450 | H14: {=SUMPRODUCT(Tracking[Amount],--(Tracking[Date]<=Tracking[[#This Row],[Date]]),(Tracking[Type]<>"Income")*(-1)+(Tracking[Type]="Income"))} -> 19550
C15: 46029 | D15: Expenses | E15: Insurances | F15: 1050 | H15: {=SUMPRODUCT(Tracking[Amount],--(Tracking[Date]<=Tracking[[#This Row],[Date]]),(Tracking[Type]<>"Income")*(-1)+(Tracking[Type]="Income"))} -> 18500
